[2024-02-13T18:56:15.886+0000] {processor.py:161} INFO - Started process (PID=49) to work on /opt/airflow/dags/star_wars_data_pipeline.py
[2024-02-13T18:56:15.887+0000] {processor.py:830} INFO - Processing file /opt/airflow/dags/star_wars_data_pipeline.py for tasks to queue
[2024-02-13T18:56:15.890+0000] {logging_mixin.py:188} INFO - [2024-02-13T18:56:15.890+0000] {dagbag.py:538} INFO - Filling up the DagBag from /opt/airflow/dags/star_wars_data_pipeline.py
[2024-02-13T18:56:15.976+0000] {logging_mixin.py:188} INFO - [2024-02-13T18:56:15.971+0000] {dagbag.py:348} ERROR - Failed to import: /opt/airflow/dags/star_wars_data_pipeline.py
Traceback (most recent call last):
  File "/home/airflow/.local/lib/python3.8/site-packages/airflow/models/dagbag.py", line 344, in parse
    loader.exec_module(new_module)
  File "<frozen importlib._bootstrap_external>", line 843, in exec_module
  File "<frozen importlib._bootstrap>", line 219, in _call_with_frames_removed
  File "/opt/airflow/dags/star_wars_data_pipeline.py", line 14, in <module>
    from script_results import generate_results_json as generate_results_json
ModuleNotFoundError: No module named 'script_results'
[2024-02-13T18:56:15.978+0000] {processor.py:842} WARNING - No viable dags retrieved from /opt/airflow/dags/star_wars_data_pipeline.py
[2024-02-13T18:56:16.007+0000] {processor.py:183} INFO - Processing /opt/airflow/dags/star_wars_data_pipeline.py took 0.125 seconds
[2024-02-13T18:56:21.076+0000] {processor.py:161} INFO - Started process (PID=50) to work on /opt/airflow/dags/star_wars_data_pipeline.py
[2024-02-13T18:56:21.077+0000] {processor.py:830} INFO - Processing file /opt/airflow/dags/star_wars_data_pipeline.py for tasks to queue
[2024-02-13T18:56:21.080+0000] {logging_mixin.py:188} INFO - [2024-02-13T18:56:21.080+0000] {dagbag.py:538} INFO - Filling up the DagBag from /opt/airflow/dags/star_wars_data_pipeline.py
[2024-02-13T18:56:21.113+0000] {logging_mixin.py:188} INFO - [2024-02-13T18:56:21.108+0000] {dagbag.py:348} ERROR - Failed to import: /opt/airflow/dags/star_wars_data_pipeline.py
Traceback (most recent call last):
  File "/home/airflow/.local/lib/python3.8/site-packages/airflow/models/dagbag.py", line 344, in parse
    loader.exec_module(new_module)
  File "<frozen importlib._bootstrap_external>", line 843, in exec_module
  File "<frozen importlib._bootstrap>", line 219, in _call_with_frames_removed
  File "/opt/airflow/dags/star_wars_data_pipeline.py", line 14, in <module>
    from script_results import generate_results_json as generate_results_json
ModuleNotFoundError: No module named 'script_results'
[2024-02-13T18:56:21.114+0000] {processor.py:842} WARNING - No viable dags retrieved from /opt/airflow/dags/star_wars_data_pipeline.py
[2024-02-13T18:56:21.928+0000] {processor.py:183} INFO - Processing /opt/airflow/dags/star_wars_data_pipeline.py took 0.855 seconds
[2024-02-13T18:56:27.745+0000] {processor.py:161} INFO - Started process (PID=59) to work on /opt/airflow/dags/star_wars_data_pipeline.py
[2024-02-13T18:56:27.748+0000] {processor.py:830} INFO - Processing file /opt/airflow/dags/star_wars_data_pipeline.py for tasks to queue
[2024-02-13T18:56:27.770+0000] {logging_mixin.py:188} INFO - [2024-02-13T18:56:27.766+0000] {dagbag.py:538} INFO - Filling up the DagBag from /opt/airflow/dags/star_wars_data_pipeline.py
[2024-02-13T18:56:27.872+0000] {logging_mixin.py:188} INFO - [2024-02-13T18:56:27.865+0000] {dagbag.py:348} ERROR - Failed to import: /opt/airflow/dags/star_wars_data_pipeline.py
Traceback (most recent call last):
  File "/home/airflow/.local/lib/python3.8/site-packages/airflow/models/dagbag.py", line 344, in parse
    loader.exec_module(new_module)
  File "<frozen importlib._bootstrap_external>", line 843, in exec_module
  File "<frozen importlib._bootstrap>", line 219, in _call_with_frames_removed
  File "/opt/airflow/dags/star_wars_data_pipeline.py", line 14, in <module>
    from script_results import generate_results_json as generate_results_json
ModuleNotFoundError: No module named 'script_results'
[2024-02-13T18:56:27.875+0000] {processor.py:842} WARNING - No viable dags retrieved from /opt/airflow/dags/star_wars_data_pipeline.py
[2024-02-13T18:56:27.914+0000] {processor.py:183} INFO - Processing /opt/airflow/dags/star_wars_data_pipeline.py took 0.224 seconds
[2024-02-13T18:56:32.988+0000] {processor.py:161} INFO - Started process (PID=60) to work on /opt/airflow/dags/star_wars_data_pipeline.py
[2024-02-13T18:56:32.990+0000] {processor.py:830} INFO - Processing file /opt/airflow/dags/star_wars_data_pipeline.py for tasks to queue
[2024-02-13T18:56:32.992+0000] {logging_mixin.py:188} INFO - [2024-02-13T18:56:32.991+0000] {dagbag.py:538} INFO - Filling up the DagBag from /opt/airflow/dags/star_wars_data_pipeline.py
[2024-02-13T18:56:33.032+0000] {logging_mixin.py:188} INFO - [2024-02-13T18:56:33.028+0000] {dagbag.py:348} ERROR - Failed to import: /opt/airflow/dags/star_wars_data_pipeline.py
Traceback (most recent call last):
  File "/home/airflow/.local/lib/python3.8/site-packages/airflow/models/dagbag.py", line 344, in parse
    loader.exec_module(new_module)
  File "<frozen importlib._bootstrap_external>", line 843, in exec_module
  File "<frozen importlib._bootstrap>", line 219, in _call_with_frames_removed
  File "/opt/airflow/dags/star_wars_data_pipeline.py", line 14, in <module>
    from script_results import generate_results_json as generate_results_json
ModuleNotFoundError: No module named 'script_results'
[2024-02-13T18:56:33.034+0000] {processor.py:842} WARNING - No viable dags retrieved from /opt/airflow/dags/star_wars_data_pipeline.py
[2024-02-13T18:56:33.075+0000] {processor.py:183} INFO - Processing /opt/airflow/dags/star_wars_data_pipeline.py took 0.089 seconds
[2024-02-13T18:56:38.157+0000] {processor.py:161} INFO - Started process (PID=68) to work on /opt/airflow/dags/star_wars_data_pipeline.py
[2024-02-13T18:56:38.159+0000] {processor.py:830} INFO - Processing file /opt/airflow/dags/star_wars_data_pipeline.py for tasks to queue
[2024-02-13T18:56:38.163+0000] {logging_mixin.py:188} INFO - [2024-02-13T18:56:38.163+0000] {dagbag.py:538} INFO - Filling up the DagBag from /opt/airflow/dags/star_wars_data_pipeline.py
[2024-02-13T18:56:38.224+0000] {logging_mixin.py:188} INFO - [2024-02-13T18:56:38.218+0000] {dagbag.py:348} ERROR - Failed to import: /opt/airflow/dags/star_wars_data_pipeline.py
Traceback (most recent call last):
  File "/home/airflow/.local/lib/python3.8/site-packages/airflow/models/dagbag.py", line 344, in parse
    loader.exec_module(new_module)
  File "<frozen importlib._bootstrap_external>", line 843, in exec_module
  File "<frozen importlib._bootstrap>", line 219, in _call_with_frames_removed
  File "/opt/airflow/dags/star_wars_data_pipeline.py", line 14, in <module>
    from script_results import generate_results_json as generate_results_json
ModuleNotFoundError: No module named 'script_results'
[2024-02-13T18:56:38.226+0000] {processor.py:842} WARNING - No viable dags retrieved from /opt/airflow/dags/star_wars_data_pipeline.py
[2024-02-13T18:56:38.259+0000] {processor.py:183} INFO - Processing /opt/airflow/dags/star_wars_data_pipeline.py took 0.106 seconds
[2024-02-13T18:56:43.465+0000] {processor.py:161} INFO - Started process (PID=70) to work on /opt/airflow/dags/star_wars_data_pipeline.py
[2024-02-13T18:56:43.466+0000] {processor.py:830} INFO - Processing file /opt/airflow/dags/star_wars_data_pipeline.py for tasks to queue
[2024-02-13T18:56:43.469+0000] {logging_mixin.py:188} INFO - [2024-02-13T18:56:43.468+0000] {dagbag.py:538} INFO - Filling up the DagBag from /opt/airflow/dags/star_wars_data_pipeline.py
[2024-02-13T18:56:43.522+0000] {logging_mixin.py:188} INFO - [2024-02-13T18:56:43.515+0000] {dagbag.py:348} ERROR - Failed to import: /opt/airflow/dags/star_wars_data_pipeline.py
Traceback (most recent call last):
  File "/home/airflow/.local/lib/python3.8/site-packages/airflow/models/dagbag.py", line 344, in parse
    loader.exec_module(new_module)
  File "<frozen importlib._bootstrap_external>", line 843, in exec_module
  File "<frozen importlib._bootstrap>", line 219, in _call_with_frames_removed
  File "/opt/airflow/dags/star_wars_data_pipeline.py", line 14, in <module>
    from script_results import generate_results_json as generate_results_json
ModuleNotFoundError: No module named 'script_results'
[2024-02-13T18:56:43.525+0000] {processor.py:842} WARNING - No viable dags retrieved from /opt/airflow/dags/star_wars_data_pipeline.py
[2024-02-13T18:56:43.564+0000] {processor.py:183} INFO - Processing /opt/airflow/dags/star_wars_data_pipeline.py took 0.101 seconds
[2024-02-13T18:56:48.632+0000] {processor.py:161} INFO - Started process (PID=71) to work on /opt/airflow/dags/star_wars_data_pipeline.py
[2024-02-13T18:56:48.634+0000] {processor.py:830} INFO - Processing file /opt/airflow/dags/star_wars_data_pipeline.py for tasks to queue
[2024-02-13T18:56:48.636+0000] {logging_mixin.py:188} INFO - [2024-02-13T18:56:48.636+0000] {dagbag.py:538} INFO - Filling up the DagBag from /opt/airflow/dags/star_wars_data_pipeline.py
[2024-02-13T18:56:48.678+0000] {logging_mixin.py:188} INFO - [2024-02-13T18:56:48.675+0000] {dagbag.py:348} ERROR - Failed to import: /opt/airflow/dags/star_wars_data_pipeline.py
Traceback (most recent call last):
  File "/home/airflow/.local/lib/python3.8/site-packages/airflow/models/dagbag.py", line 344, in parse
    loader.exec_module(new_module)
  File "<frozen importlib._bootstrap_external>", line 843, in exec_module
  File "<frozen importlib._bootstrap>", line 219, in _call_with_frames_removed
  File "/opt/airflow/dags/star_wars_data_pipeline.py", line 14, in <module>
    from script_results import generate_results_json as generate_results_json
ModuleNotFoundError: No module named 'script_results'
[2024-02-13T18:56:48.680+0000] {processor.py:842} WARNING - No viable dags retrieved from /opt/airflow/dags/star_wars_data_pipeline.py
[2024-02-13T18:56:48.703+0000] {processor.py:183} INFO - Processing /opt/airflow/dags/star_wars_data_pipeline.py took 0.073 seconds
[2024-02-13T18:56:53.770+0000] {processor.py:161} INFO - Started process (PID=80) to work on /opt/airflow/dags/star_wars_data_pipeline.py
[2024-02-13T18:56:53.772+0000] {processor.py:830} INFO - Processing file /opt/airflow/dags/star_wars_data_pipeline.py for tasks to queue
[2024-02-13T18:56:53.774+0000] {logging_mixin.py:188} INFO - [2024-02-13T18:56:53.774+0000] {dagbag.py:538} INFO - Filling up the DagBag from /opt/airflow/dags/star_wars_data_pipeline.py
[2024-02-13T18:56:53.817+0000] {logging_mixin.py:188} INFO - [2024-02-13T18:56:53.812+0000] {dagbag.py:348} ERROR - Failed to import: /opt/airflow/dags/star_wars_data_pipeline.py
Traceback (most recent call last):
  File "/home/airflow/.local/lib/python3.8/site-packages/airflow/models/dagbag.py", line 344, in parse
    loader.exec_module(new_module)
  File "<frozen importlib._bootstrap_external>", line 843, in exec_module
  File "<frozen importlib._bootstrap>", line 219, in _call_with_frames_removed
  File "/opt/airflow/dags/star_wars_data_pipeline.py", line 14, in <module>
    from script_results import generate_results_json as generate_results_json
ModuleNotFoundError: No module named 'script_results'
[2024-02-13T18:56:53.819+0000] {processor.py:842} WARNING - No viable dags retrieved from /opt/airflow/dags/star_wars_data_pipeline.py
[2024-02-13T18:56:53.846+0000] {processor.py:183} INFO - Processing /opt/airflow/dags/star_wars_data_pipeline.py took 0.078 seconds
[2024-02-13T18:56:58.903+0000] {processor.py:161} INFO - Started process (PID=81) to work on /opt/airflow/dags/star_wars_data_pipeline.py
[2024-02-13T18:56:58.904+0000] {processor.py:830} INFO - Processing file /opt/airflow/dags/star_wars_data_pipeline.py for tasks to queue
[2024-02-13T18:56:58.907+0000] {logging_mixin.py:188} INFO - [2024-02-13T18:56:58.907+0000] {dagbag.py:538} INFO - Filling up the DagBag from /opt/airflow/dags/star_wars_data_pipeline.py
[2024-02-13T18:56:58.949+0000] {logging_mixin.py:188} INFO - [2024-02-13T18:56:58.944+0000] {dagbag.py:348} ERROR - Failed to import: /opt/airflow/dags/star_wars_data_pipeline.py
Traceback (most recent call last):
  File "/home/airflow/.local/lib/python3.8/site-packages/airflow/models/dagbag.py", line 344, in parse
    loader.exec_module(new_module)
  File "<frozen importlib._bootstrap_external>", line 843, in exec_module
  File "<frozen importlib._bootstrap>", line 219, in _call_with_frames_removed
  File "/opt/airflow/dags/star_wars_data_pipeline.py", line 14, in <module>
    from script_results import generate_results_json as generate_results_json
ModuleNotFoundError: No module named 'script_results'
[2024-02-13T18:56:58.951+0000] {processor.py:842} WARNING - No viable dags retrieved from /opt/airflow/dags/star_wars_data_pipeline.py
[2024-02-13T18:56:58.979+0000] {processor.py:183} INFO - Processing /opt/airflow/dags/star_wars_data_pipeline.py took 0.083 seconds
[2024-02-13T18:57:04.051+0000] {processor.py:161} INFO - Started process (PID=82) to work on /opt/airflow/dags/star_wars_data_pipeline.py
[2024-02-13T18:57:04.052+0000] {processor.py:830} INFO - Processing file /opt/airflow/dags/star_wars_data_pipeline.py for tasks to queue
[2024-02-13T18:57:04.055+0000] {logging_mixin.py:188} INFO - [2024-02-13T18:57:04.054+0000] {dagbag.py:538} INFO - Filling up the DagBag from /opt/airflow/dags/star_wars_data_pipeline.py
[2024-02-13T18:57:04.094+0000] {logging_mixin.py:188} INFO - [2024-02-13T18:57:04.089+0000] {dagbag.py:348} ERROR - Failed to import: /opt/airflow/dags/star_wars_data_pipeline.py
Traceback (most recent call last):
  File "/home/airflow/.local/lib/python3.8/site-packages/airflow/models/dagbag.py", line 344, in parse
    loader.exec_module(new_module)
  File "<frozen importlib._bootstrap_external>", line 843, in exec_module
  File "<frozen importlib._bootstrap>", line 219, in _call_with_frames_removed
  File "/opt/airflow/dags/star_wars_data_pipeline.py", line 14, in <module>
    from script_results import generate_results_json as generate_results_json
ModuleNotFoundError: No module named 'script_results'
[2024-02-13T18:57:04.095+0000] {processor.py:842} WARNING - No viable dags retrieved from /opt/airflow/dags/star_wars_data_pipeline.py
[2024-02-13T18:57:04.117+0000] {processor.py:183} INFO - Processing /opt/airflow/dags/star_wars_data_pipeline.py took 0.070 seconds
[2024-02-13T18:57:09.196+0000] {processor.py:161} INFO - Started process (PID=91) to work on /opt/airflow/dags/star_wars_data_pipeline.py
[2024-02-13T18:57:09.198+0000] {processor.py:830} INFO - Processing file /opt/airflow/dags/star_wars_data_pipeline.py for tasks to queue
[2024-02-13T18:57:09.200+0000] {logging_mixin.py:188} INFO - [2024-02-13T18:57:09.200+0000] {dagbag.py:538} INFO - Filling up the DagBag from /opt/airflow/dags/star_wars_data_pipeline.py
[2024-02-13T18:57:09.243+0000] {logging_mixin.py:188} INFO - [2024-02-13T18:57:09.238+0000] {dagbag.py:348} ERROR - Failed to import: /opt/airflow/dags/star_wars_data_pipeline.py
Traceback (most recent call last):
  File "/home/airflow/.local/lib/python3.8/site-packages/airflow/models/dagbag.py", line 344, in parse
    loader.exec_module(new_module)
  File "<frozen importlib._bootstrap_external>", line 843, in exec_module
  File "<frozen importlib._bootstrap>", line 219, in _call_with_frames_removed
  File "/opt/airflow/dags/star_wars_data_pipeline.py", line 14, in <module>
    from script_results import generate_results_json as generate_results_json
ModuleNotFoundError: No module named 'script_results'
[2024-02-13T18:57:09.245+0000] {processor.py:842} WARNING - No viable dags retrieved from /opt/airflow/dags/star_wars_data_pipeline.py
[2024-02-13T18:57:09.272+0000] {processor.py:183} INFO - Processing /opt/airflow/dags/star_wars_data_pipeline.py took 0.081 seconds
[2024-02-13T18:57:14.339+0000] {processor.py:161} INFO - Started process (PID=92) to work on /opt/airflow/dags/star_wars_data_pipeline.py
[2024-02-13T18:57:14.340+0000] {processor.py:830} INFO - Processing file /opt/airflow/dags/star_wars_data_pipeline.py for tasks to queue
[2024-02-13T18:57:14.343+0000] {logging_mixin.py:188} INFO - [2024-02-13T18:57:14.343+0000] {dagbag.py:538} INFO - Filling up the DagBag from /opt/airflow/dags/star_wars_data_pipeline.py
[2024-02-13T18:57:14.381+0000] {logging_mixin.py:188} INFO - [2024-02-13T18:57:14.376+0000] {dagbag.py:348} ERROR - Failed to import: /opt/airflow/dags/star_wars_data_pipeline.py
Traceback (most recent call last):
  File "/home/airflow/.local/lib/python3.8/site-packages/airflow/models/dagbag.py", line 344, in parse
    loader.exec_module(new_module)
  File "<frozen importlib._bootstrap_external>", line 843, in exec_module
  File "<frozen importlib._bootstrap>", line 219, in _call_with_frames_removed
  File "/opt/airflow/dags/star_wars_data_pipeline.py", line 14, in <module>
    from script_results import generate_results_json as generate_results_json
ModuleNotFoundError: No module named 'script_results'
[2024-02-13T18:57:14.383+0000] {processor.py:842} WARNING - No viable dags retrieved from /opt/airflow/dags/star_wars_data_pipeline.py
[2024-02-13T18:57:14.412+0000] {processor.py:183} INFO - Processing /opt/airflow/dags/star_wars_data_pipeline.py took 0.076 seconds
[2024-02-13T18:57:19.458+0000] {processor.py:161} INFO - Started process (PID=101) to work on /opt/airflow/dags/star_wars_data_pipeline.py
[2024-02-13T18:57:19.459+0000] {processor.py:830} INFO - Processing file /opt/airflow/dags/star_wars_data_pipeline.py for tasks to queue
[2024-02-13T18:57:19.462+0000] {logging_mixin.py:188} INFO - [2024-02-13T18:57:19.462+0000] {dagbag.py:538} INFO - Filling up the DagBag from /opt/airflow/dags/star_wars_data_pipeline.py
[2024-02-13T18:57:19.504+0000] {logging_mixin.py:188} INFO - [2024-02-13T18:57:19.500+0000] {dagbag.py:348} ERROR - Failed to import: /opt/airflow/dags/star_wars_data_pipeline.py
Traceback (most recent call last):
  File "/home/airflow/.local/lib/python3.8/site-packages/airflow/models/dagbag.py", line 344, in parse
    loader.exec_module(new_module)
  File "<frozen importlib._bootstrap_external>", line 843, in exec_module
  File "<frozen importlib._bootstrap>", line 219, in _call_with_frames_removed
  File "/opt/airflow/dags/star_wars_data_pipeline.py", line 14, in <module>
    from script_results import generate_results_json as generate_results_json
ModuleNotFoundError: No module named 'script_results'
[2024-02-13T18:57:19.506+0000] {processor.py:842} WARNING - No viable dags retrieved from /opt/airflow/dags/star_wars_data_pipeline.py
[2024-02-13T18:57:19.537+0000] {processor.py:183} INFO - Processing /opt/airflow/dags/star_wars_data_pipeline.py took 0.082 seconds
[2024-02-13T18:57:24.604+0000] {processor.py:161} INFO - Started process (PID=102) to work on /opt/airflow/dags/star_wars_data_pipeline.py
[2024-02-13T18:57:24.605+0000] {processor.py:830} INFO - Processing file /opt/airflow/dags/star_wars_data_pipeline.py for tasks to queue
[2024-02-13T18:57:24.607+0000] {logging_mixin.py:188} INFO - [2024-02-13T18:57:24.607+0000] {dagbag.py:538} INFO - Filling up the DagBag from /opt/airflow/dags/star_wars_data_pipeline.py
[2024-02-13T18:57:24.642+0000] {logging_mixin.py:188} INFO - [2024-02-13T18:57:24.637+0000] {dagbag.py:348} ERROR - Failed to import: /opt/airflow/dags/star_wars_data_pipeline.py
Traceback (most recent call last):
  File "/home/airflow/.local/lib/python3.8/site-packages/airflow/models/dagbag.py", line 344, in parse
    loader.exec_module(new_module)
  File "<frozen importlib._bootstrap_external>", line 843, in exec_module
  File "<frozen importlib._bootstrap>", line 219, in _call_with_frames_removed
  File "/opt/airflow/dags/star_wars_data_pipeline.py", line 14, in <module>
    from script_results import generate_results_json as generate_results_json
ModuleNotFoundError: No module named 'script_results'
[2024-02-13T18:57:24.643+0000] {processor.py:842} WARNING - No viable dags retrieved from /opt/airflow/dags/star_wars_data_pipeline.py
[2024-02-13T18:57:24.665+0000] {processor.py:183} INFO - Processing /opt/airflow/dags/star_wars_data_pipeline.py took 0.063 seconds
[2024-02-13T18:57:29.732+0000] {processor.py:161} INFO - Started process (PID=103) to work on /opt/airflow/dags/star_wars_data_pipeline.py
[2024-02-13T18:57:29.734+0000] {processor.py:830} INFO - Processing file /opt/airflow/dags/star_wars_data_pipeline.py for tasks to queue
[2024-02-13T18:57:29.735+0000] {logging_mixin.py:188} INFO - [2024-02-13T18:57:29.735+0000] {dagbag.py:538} INFO - Filling up the DagBag from /opt/airflow/dags/star_wars_data_pipeline.py
[2024-02-13T18:57:29.772+0000] {logging_mixin.py:188} INFO - [2024-02-13T18:57:29.768+0000] {dagbag.py:348} ERROR - Failed to import: /opt/airflow/dags/star_wars_data_pipeline.py
Traceback (most recent call last):
  File "/home/airflow/.local/lib/python3.8/site-packages/airflow/models/dagbag.py", line 344, in parse
    loader.exec_module(new_module)
  File "<frozen importlib._bootstrap_external>", line 843, in exec_module
  File "<frozen importlib._bootstrap>", line 219, in _call_with_frames_removed
  File "/opt/airflow/dags/star_wars_data_pipeline.py", line 14, in <module>
    from script_results import generate_results_json as generate_results_json
ModuleNotFoundError: No module named 'script_results'
[2024-02-13T18:57:29.773+0000] {processor.py:842} WARNING - No viable dags retrieved from /opt/airflow/dags/star_wars_data_pipeline.py
[2024-02-13T18:57:29.798+0000] {processor.py:183} INFO - Processing /opt/airflow/dags/star_wars_data_pipeline.py took 0.069 seconds
[2024-02-13T18:57:34.867+0000] {processor.py:161} INFO - Started process (PID=112) to work on /opt/airflow/dags/star_wars_data_pipeline.py
[2024-02-13T18:57:34.868+0000] {processor.py:830} INFO - Processing file /opt/airflow/dags/star_wars_data_pipeline.py for tasks to queue
[2024-02-13T18:57:34.871+0000] {logging_mixin.py:188} INFO - [2024-02-13T18:57:34.871+0000] {dagbag.py:538} INFO - Filling up the DagBag from /opt/airflow/dags/star_wars_data_pipeline.py
[2024-02-13T18:57:34.911+0000] {logging_mixin.py:188} INFO - [2024-02-13T18:57:34.907+0000] {dagbag.py:348} ERROR - Failed to import: /opt/airflow/dags/star_wars_data_pipeline.py
Traceback (most recent call last):
  File "/home/airflow/.local/lib/python3.8/site-packages/airflow/models/dagbag.py", line 344, in parse
    loader.exec_module(new_module)
  File "<frozen importlib._bootstrap_external>", line 843, in exec_module
  File "<frozen importlib._bootstrap>", line 219, in _call_with_frames_removed
  File "/opt/airflow/dags/star_wars_data_pipeline.py", line 14, in <module>
    from script_results import generate_results_json as generate_results_json
ModuleNotFoundError: No module named 'script_results'
[2024-02-13T18:57:34.913+0000] {processor.py:842} WARNING - No viable dags retrieved from /opt/airflow/dags/star_wars_data_pipeline.py
[2024-02-13T18:57:34.936+0000] {processor.py:183} INFO - Processing /opt/airflow/dags/star_wars_data_pipeline.py took 0.072 seconds
[2024-02-13T18:57:39.980+0000] {processor.py:161} INFO - Started process (PID=113) to work on /opt/airflow/dags/star_wars_data_pipeline.py
[2024-02-13T18:57:39.981+0000] {processor.py:830} INFO - Processing file /opt/airflow/dags/star_wars_data_pipeline.py for tasks to queue
[2024-02-13T18:57:39.983+0000] {logging_mixin.py:188} INFO - [2024-02-13T18:57:39.983+0000] {dagbag.py:538} INFO - Filling up the DagBag from /opt/airflow/dags/star_wars_data_pipeline.py
[2024-02-13T18:57:40.015+0000] {logging_mixin.py:188} INFO - [2024-02-13T18:57:40.011+0000] {dagbag.py:348} ERROR - Failed to import: /opt/airflow/dags/star_wars_data_pipeline.py
Traceback (most recent call last):
  File "/home/airflow/.local/lib/python3.8/site-packages/airflow/models/dagbag.py", line 344, in parse
    loader.exec_module(new_module)
  File "<frozen importlib._bootstrap_external>", line 843, in exec_module
  File "<frozen importlib._bootstrap>", line 219, in _call_with_frames_removed
  File "/opt/airflow/dags/star_wars_data_pipeline.py", line 14, in <module>
    from script_results import generate_results_json as generate_results_json
ModuleNotFoundError: No module named 'script_results'
[2024-02-13T18:57:40.017+0000] {processor.py:842} WARNING - No viable dags retrieved from /opt/airflow/dags/star_wars_data_pipeline.py
[2024-02-13T18:57:40.041+0000] {processor.py:183} INFO - Processing /opt/airflow/dags/star_wars_data_pipeline.py took 0.064 seconds
[2024-02-13T18:57:45.122+0000] {processor.py:161} INFO - Started process (PID=122) to work on /opt/airflow/dags/star_wars_data_pipeline.py
[2024-02-13T18:57:45.123+0000] {processor.py:830} INFO - Processing file /opt/airflow/dags/star_wars_data_pipeline.py for tasks to queue
[2024-02-13T18:57:45.126+0000] {logging_mixin.py:188} INFO - [2024-02-13T18:57:45.126+0000] {dagbag.py:538} INFO - Filling up the DagBag from /opt/airflow/dags/star_wars_data_pipeline.py
[2024-02-13T18:57:45.178+0000] {logging_mixin.py:188} INFO - [2024-02-13T18:57:45.172+0000] {dagbag.py:348} ERROR - Failed to import: /opt/airflow/dags/star_wars_data_pipeline.py
Traceback (most recent call last):
  File "/home/airflow/.local/lib/python3.8/site-packages/airflow/models/dagbag.py", line 344, in parse
    loader.exec_module(new_module)
  File "<frozen importlib._bootstrap_external>", line 843, in exec_module
  File "<frozen importlib._bootstrap>", line 219, in _call_with_frames_removed
  File "/opt/airflow/dags/star_wars_data_pipeline.py", line 14, in <module>
    from script_results import generate_results_json as generate_results_json
ModuleNotFoundError: No module named 'script_results'
[2024-02-13T18:57:45.180+0000] {processor.py:842} WARNING - No viable dags retrieved from /opt/airflow/dags/star_wars_data_pipeline.py
[2024-02-13T18:57:45.205+0000] {processor.py:183} INFO - Processing /opt/airflow/dags/star_wars_data_pipeline.py took 0.088 seconds
[2024-02-13T18:57:50.273+0000] {processor.py:161} INFO - Started process (PID=123) to work on /opt/airflow/dags/star_wars_data_pipeline.py
[2024-02-13T18:57:50.278+0000] {processor.py:830} INFO - Processing file /opt/airflow/dags/star_wars_data_pipeline.py for tasks to queue
[2024-02-13T18:57:50.281+0000] {logging_mixin.py:188} INFO - [2024-02-13T18:57:50.280+0000] {dagbag.py:538} INFO - Filling up the DagBag from /opt/airflow/dags/star_wars_data_pipeline.py
[2024-02-13T18:57:50.315+0000] {logging_mixin.py:188} INFO - [2024-02-13T18:57:50.311+0000] {dagbag.py:348} ERROR - Failed to import: /opt/airflow/dags/star_wars_data_pipeline.py
Traceback (most recent call last):
  File "/home/airflow/.local/lib/python3.8/site-packages/airflow/models/dagbag.py", line 344, in parse
    loader.exec_module(new_module)
  File "<frozen importlib._bootstrap_external>", line 843, in exec_module
  File "<frozen importlib._bootstrap>", line 219, in _call_with_frames_removed
  File "/opt/airflow/dags/star_wars_data_pipeline.py", line 14, in <module>
    from script_results import generate_results_json as generate_results_json
ModuleNotFoundError: No module named 'script_results'
[2024-02-13T18:57:50.316+0000] {processor.py:842} WARNING - No viable dags retrieved from /opt/airflow/dags/star_wars_data_pipeline.py
[2024-02-13T18:57:50.336+0000] {processor.py:183} INFO - Processing /opt/airflow/dags/star_wars_data_pipeline.py took 0.065 seconds
[2024-02-13T18:57:55.405+0000] {processor.py:161} INFO - Started process (PID=124) to work on /opt/airflow/dags/star_wars_data_pipeline.py
[2024-02-13T18:57:55.407+0000] {processor.py:830} INFO - Processing file /opt/airflow/dags/star_wars_data_pipeline.py for tasks to queue
[2024-02-13T18:57:55.410+0000] {logging_mixin.py:188} INFO - [2024-02-13T18:57:55.409+0000] {dagbag.py:538} INFO - Filling up the DagBag from /opt/airflow/dags/star_wars_data_pipeline.py
[2024-02-13T18:57:55.448+0000] {logging_mixin.py:188} INFO - [2024-02-13T18:57:55.444+0000] {dagbag.py:348} ERROR - Failed to import: /opt/airflow/dags/star_wars_data_pipeline.py
Traceback (most recent call last):
  File "/home/airflow/.local/lib/python3.8/site-packages/airflow/models/dagbag.py", line 344, in parse
    loader.exec_module(new_module)
  File "<frozen importlib._bootstrap_external>", line 843, in exec_module
  File "<frozen importlib._bootstrap>", line 219, in _call_with_frames_removed
  File "/opt/airflow/dags/star_wars_data_pipeline.py", line 14, in <module>
    from script_results import generate_results_json as generate_results_json
ModuleNotFoundError: No module named 'script_results'
[2024-02-13T18:57:55.451+0000] {processor.py:842} WARNING - No viable dags retrieved from /opt/airflow/dags/star_wars_data_pipeline.py
[2024-02-13T18:57:55.472+0000] {processor.py:183} INFO - Processing /opt/airflow/dags/star_wars_data_pipeline.py took 0.069 seconds
[2024-02-13T18:58:00.538+0000] {processor.py:161} INFO - Started process (PID=133) to work on /opt/airflow/dags/star_wars_data_pipeline.py
[2024-02-13T18:58:00.539+0000] {processor.py:830} INFO - Processing file /opt/airflow/dags/star_wars_data_pipeline.py for tasks to queue
[2024-02-13T18:58:00.542+0000] {logging_mixin.py:188} INFO - [2024-02-13T18:58:00.541+0000] {dagbag.py:538} INFO - Filling up the DagBag from /opt/airflow/dags/star_wars_data_pipeline.py
[2024-02-13T18:58:00.581+0000] {logging_mixin.py:188} INFO - [2024-02-13T18:58:00.577+0000] {dagbag.py:348} ERROR - Failed to import: /opt/airflow/dags/star_wars_data_pipeline.py
Traceback (most recent call last):
  File "/home/airflow/.local/lib/python3.8/site-packages/airflow/models/dagbag.py", line 344, in parse
    loader.exec_module(new_module)
  File "<frozen importlib._bootstrap_external>", line 843, in exec_module
  File "<frozen importlib._bootstrap>", line 219, in _call_with_frames_removed
  File "/opt/airflow/dags/star_wars_data_pipeline.py", line 14, in <module>
    from script_results import generate_results_json as generate_results_json
ModuleNotFoundError: No module named 'script_results'
[2024-02-13T18:58:00.583+0000] {processor.py:842} WARNING - No viable dags retrieved from /opt/airflow/dags/star_wars_data_pipeline.py
[2024-02-13T18:58:00.604+0000] {processor.py:183} INFO - Processing /opt/airflow/dags/star_wars_data_pipeline.py took 0.068 seconds
[2024-02-13T18:58:05.670+0000] {processor.py:161} INFO - Started process (PID=134) to work on /opt/airflow/dags/star_wars_data_pipeline.py
[2024-02-13T18:58:05.671+0000] {processor.py:830} INFO - Processing file /opt/airflow/dags/star_wars_data_pipeline.py for tasks to queue
[2024-02-13T18:58:05.674+0000] {logging_mixin.py:188} INFO - [2024-02-13T18:58:05.674+0000] {dagbag.py:538} INFO - Filling up the DagBag from /opt/airflow/dags/star_wars_data_pipeline.py
[2024-02-13T18:58:05.711+0000] {logging_mixin.py:188} INFO - [2024-02-13T18:58:05.707+0000] {dagbag.py:348} ERROR - Failed to import: /opt/airflow/dags/star_wars_data_pipeline.py
Traceback (most recent call last):
  File "/home/airflow/.local/lib/python3.8/site-packages/airflow/models/dagbag.py", line 344, in parse
    loader.exec_module(new_module)
  File "<frozen importlib._bootstrap_external>", line 843, in exec_module
  File "<frozen importlib._bootstrap>", line 219, in _call_with_frames_removed
  File "/opt/airflow/dags/star_wars_data_pipeline.py", line 14, in <module>
    from script_results import generate_results_json as generate_results_json
ModuleNotFoundError: No module named 'script_results'
[2024-02-13T18:58:05.713+0000] {processor.py:842} WARNING - No viable dags retrieved from /opt/airflow/dags/star_wars_data_pipeline.py
[2024-02-13T18:58:05.735+0000] {processor.py:183} INFO - Processing /opt/airflow/dags/star_wars_data_pipeline.py took 0.067 seconds
[2024-02-13T18:58:10.810+0000] {processor.py:161} INFO - Started process (PID=143) to work on /opt/airflow/dags/star_wars_data_pipeline.py
[2024-02-13T18:58:10.811+0000] {processor.py:830} INFO - Processing file /opt/airflow/dags/star_wars_data_pipeline.py for tasks to queue
[2024-02-13T18:58:10.815+0000] {logging_mixin.py:188} INFO - [2024-02-13T18:58:10.814+0000] {dagbag.py:538} INFO - Filling up the DagBag from /opt/airflow/dags/star_wars_data_pipeline.py
[2024-02-13T18:58:10.856+0000] {logging_mixin.py:188} INFO - [2024-02-13T18:58:10.851+0000] {dagbag.py:348} ERROR - Failed to import: /opt/airflow/dags/star_wars_data_pipeline.py
Traceback (most recent call last):
  File "/home/airflow/.local/lib/python3.8/site-packages/airflow/models/dagbag.py", line 344, in parse
    loader.exec_module(new_module)
  File "<frozen importlib._bootstrap_external>", line 843, in exec_module
  File "<frozen importlib._bootstrap>", line 219, in _call_with_frames_removed
  File "/opt/airflow/dags/star_wars_data_pipeline.py", line 14, in <module>
    from script_results import generate_results_json as generate_results_json
ModuleNotFoundError: No module named 'script_results'
[2024-02-13T18:58:10.858+0000] {processor.py:842} WARNING - No viable dags retrieved from /opt/airflow/dags/star_wars_data_pipeline.py
[2024-02-13T18:58:10.888+0000] {processor.py:183} INFO - Processing /opt/airflow/dags/star_wars_data_pipeline.py took 0.082 seconds
[2024-02-13T18:58:15.959+0000] {processor.py:161} INFO - Started process (PID=144) to work on /opt/airflow/dags/star_wars_data_pipeline.py
[2024-02-13T18:58:15.960+0000] {processor.py:830} INFO - Processing file /opt/airflow/dags/star_wars_data_pipeline.py for tasks to queue
[2024-02-13T18:58:15.962+0000] {logging_mixin.py:188} INFO - [2024-02-13T18:58:15.962+0000] {dagbag.py:538} INFO - Filling up the DagBag from /opt/airflow/dags/star_wars_data_pipeline.py
[2024-02-13T18:58:15.999+0000] {logging_mixin.py:188} INFO - [2024-02-13T18:58:15.994+0000] {dagbag.py:348} ERROR - Failed to import: /opt/airflow/dags/star_wars_data_pipeline.py
Traceback (most recent call last):
  File "/home/airflow/.local/lib/python3.8/site-packages/airflow/models/dagbag.py", line 344, in parse
    loader.exec_module(new_module)
  File "<frozen importlib._bootstrap_external>", line 843, in exec_module
  File "<frozen importlib._bootstrap>", line 219, in _call_with_frames_removed
  File "/opt/airflow/dags/star_wars_data_pipeline.py", line 14, in <module>
    from script_results import generate_results_json as generate_results_json
ModuleNotFoundError: No module named 'script_results'
[2024-02-13T18:58:16.000+0000] {processor.py:842} WARNING - No viable dags retrieved from /opt/airflow/dags/star_wars_data_pipeline.py
[2024-02-13T18:58:16.024+0000] {processor.py:183} INFO - Processing /opt/airflow/dags/star_wars_data_pipeline.py took 0.067 seconds
[2024-02-13T18:58:21.093+0000] {processor.py:161} INFO - Started process (PID=145) to work on /opt/airflow/dags/star_wars_data_pipeline.py
[2024-02-13T18:58:21.095+0000] {processor.py:830} INFO - Processing file /opt/airflow/dags/star_wars_data_pipeline.py for tasks to queue
[2024-02-13T18:58:21.096+0000] {logging_mixin.py:188} INFO - [2024-02-13T18:58:21.096+0000] {dagbag.py:538} INFO - Filling up the DagBag from /opt/airflow/dags/star_wars_data_pipeline.py
[2024-02-13T18:58:21.129+0000] {logging_mixin.py:188} INFO - [2024-02-13T18:58:21.125+0000] {dagbag.py:348} ERROR - Failed to import: /opt/airflow/dags/star_wars_data_pipeline.py
Traceback (most recent call last):
  File "/home/airflow/.local/lib/python3.8/site-packages/airflow/models/dagbag.py", line 344, in parse
    loader.exec_module(new_module)
  File "<frozen importlib._bootstrap_external>", line 843, in exec_module
  File "<frozen importlib._bootstrap>", line 219, in _call_with_frames_removed
  File "/opt/airflow/dags/star_wars_data_pipeline.py", line 14, in <module>
    from script_results import generate_results_json as generate_results_json
ModuleNotFoundError: No module named 'script_results'
[2024-02-13T18:58:21.131+0000] {processor.py:842} WARNING - No viable dags retrieved from /opt/airflow/dags/star_wars_data_pipeline.py
[2024-02-13T18:58:21.151+0000] {processor.py:183} INFO - Processing /opt/airflow/dags/star_wars_data_pipeline.py took 0.060 seconds
[2024-02-13T18:58:26.218+0000] {processor.py:161} INFO - Started process (PID=154) to work on /opt/airflow/dags/star_wars_data_pipeline.py
[2024-02-13T18:58:26.220+0000] {processor.py:830} INFO - Processing file /opt/airflow/dags/star_wars_data_pipeline.py for tasks to queue
[2024-02-13T18:58:26.222+0000] {logging_mixin.py:188} INFO - [2024-02-13T18:58:26.222+0000] {dagbag.py:538} INFO - Filling up the DagBag from /opt/airflow/dags/star_wars_data_pipeline.py
[2024-02-13T18:58:26.258+0000] {logging_mixin.py:188} INFO - [2024-02-13T18:58:26.254+0000] {dagbag.py:348} ERROR - Failed to import: /opt/airflow/dags/star_wars_data_pipeline.py
Traceback (most recent call last):
  File "/home/airflow/.local/lib/python3.8/site-packages/airflow/models/dagbag.py", line 344, in parse
    loader.exec_module(new_module)
  File "<frozen importlib._bootstrap_external>", line 843, in exec_module
  File "<frozen importlib._bootstrap>", line 219, in _call_with_frames_removed
  File "/opt/airflow/dags/star_wars_data_pipeline.py", line 14, in <module>
    from script_results import generate_results_json as generate_results_json
ModuleNotFoundError: No module named 'script_results'
[2024-02-13T18:58:26.259+0000] {processor.py:842} WARNING - No viable dags retrieved from /opt/airflow/dags/star_wars_data_pipeline.py
[2024-02-13T18:58:26.283+0000] {processor.py:183} INFO - Processing /opt/airflow/dags/star_wars_data_pipeline.py took 0.067 seconds
[2024-02-13T18:58:31.354+0000] {processor.py:161} INFO - Started process (PID=155) to work on /opt/airflow/dags/star_wars_data_pipeline.py
[2024-02-13T18:58:31.355+0000] {processor.py:830} INFO - Processing file /opt/airflow/dags/star_wars_data_pipeline.py for tasks to queue
[2024-02-13T18:58:31.358+0000] {logging_mixin.py:188} INFO - [2024-02-13T18:58:31.357+0000] {dagbag.py:538} INFO - Filling up the DagBag from /opt/airflow/dags/star_wars_data_pipeline.py
[2024-02-13T18:58:31.392+0000] {logging_mixin.py:188} INFO - [2024-02-13T18:58:31.388+0000] {dagbag.py:348} ERROR - Failed to import: /opt/airflow/dags/star_wars_data_pipeline.py
Traceback (most recent call last):
  File "/home/airflow/.local/lib/python3.8/site-packages/airflow/models/dagbag.py", line 344, in parse
    loader.exec_module(new_module)
  File "<frozen importlib._bootstrap_external>", line 843, in exec_module
  File "<frozen importlib._bootstrap>", line 219, in _call_with_frames_removed
  File "/opt/airflow/dags/star_wars_data_pipeline.py", line 14, in <module>
    from script_results import generate_results_json as generate_results_json
ModuleNotFoundError: No module named 'script_results'
[2024-02-13T18:58:31.393+0000] {processor.py:842} WARNING - No viable dags retrieved from /opt/airflow/dags/star_wars_data_pipeline.py
[2024-02-13T18:58:31.421+0000] {processor.py:183} INFO - Processing /opt/airflow/dags/star_wars_data_pipeline.py took 0.068 seconds
[2024-02-13T18:58:36.492+0000] {processor.py:161} INFO - Started process (PID=164) to work on /opt/airflow/dags/star_wars_data_pipeline.py
[2024-02-13T18:58:36.493+0000] {processor.py:830} INFO - Processing file /opt/airflow/dags/star_wars_data_pipeline.py for tasks to queue
[2024-02-13T18:58:36.496+0000] {logging_mixin.py:188} INFO - [2024-02-13T18:58:36.495+0000] {dagbag.py:538} INFO - Filling up the DagBag from /opt/airflow/dags/star_wars_data_pipeline.py
[2024-02-13T18:58:36.538+0000] {logging_mixin.py:188} INFO - [2024-02-13T18:58:36.534+0000] {dagbag.py:348} ERROR - Failed to import: /opt/airflow/dags/star_wars_data_pipeline.py
Traceback (most recent call last):
  File "/home/airflow/.local/lib/python3.8/site-packages/airflow/models/dagbag.py", line 344, in parse
    loader.exec_module(new_module)
  File "<frozen importlib._bootstrap_external>", line 843, in exec_module
  File "<frozen importlib._bootstrap>", line 219, in _call_with_frames_removed
  File "/opt/airflow/dags/star_wars_data_pipeline.py", line 14, in <module>
    from script_results import generate_results_json as generate_results_json
ModuleNotFoundError: No module named 'script_results'
[2024-02-13T18:58:36.539+0000] {processor.py:842} WARNING - No viable dags retrieved from /opt/airflow/dags/star_wars_data_pipeline.py
[2024-02-13T18:58:36.562+0000] {processor.py:183} INFO - Processing /opt/airflow/dags/star_wars_data_pipeline.py took 0.073 seconds
[2024-02-13T18:58:41.598+0000] {processor.py:161} INFO - Started process (PID=165) to work on /opt/airflow/dags/star_wars_data_pipeline.py
[2024-02-13T18:58:41.600+0000] {processor.py:830} INFO - Processing file /opt/airflow/dags/star_wars_data_pipeline.py for tasks to queue
[2024-02-13T18:58:41.602+0000] {logging_mixin.py:188} INFO - [2024-02-13T18:58:41.602+0000] {dagbag.py:538} INFO - Filling up the DagBag from /opt/airflow/dags/star_wars_data_pipeline.py
[2024-02-13T18:58:41.634+0000] {logging_mixin.py:188} INFO - [2024-02-13T18:58:41.631+0000] {dagbag.py:348} ERROR - Failed to import: /opt/airflow/dags/star_wars_data_pipeline.py
Traceback (most recent call last):
  File "/home/airflow/.local/lib/python3.8/site-packages/airflow/models/dagbag.py", line 344, in parse
    loader.exec_module(new_module)
  File "<frozen importlib._bootstrap_external>", line 843, in exec_module
  File "<frozen importlib._bootstrap>", line 219, in _call_with_frames_removed
  File "/opt/airflow/dags/star_wars_data_pipeline.py", line 14, in <module>
    from script_results import generate_results_json as generate_results_json
ModuleNotFoundError: No module named 'script_results'
[2024-02-13T18:58:41.636+0000] {processor.py:842} WARNING - No viable dags retrieved from /opt/airflow/dags/star_wars_data_pipeline.py
[2024-02-13T18:58:41.664+0000] {processor.py:183} INFO - Processing /opt/airflow/dags/star_wars_data_pipeline.py took 0.068 seconds
[2024-02-13T18:58:46.730+0000] {processor.py:161} INFO - Started process (PID=166) to work on /opt/airflow/dags/star_wars_data_pipeline.py
[2024-02-13T18:58:46.731+0000] {processor.py:830} INFO - Processing file /opt/airflow/dags/star_wars_data_pipeline.py for tasks to queue
[2024-02-13T18:58:46.733+0000] {logging_mixin.py:188} INFO - [2024-02-13T18:58:46.733+0000] {dagbag.py:538} INFO - Filling up the DagBag from /opt/airflow/dags/star_wars_data_pipeline.py
[2024-02-13T18:58:46.768+0000] {logging_mixin.py:188} INFO - [2024-02-13T18:58:46.764+0000] {dagbag.py:348} ERROR - Failed to import: /opt/airflow/dags/star_wars_data_pipeline.py
Traceback (most recent call last):
  File "/home/airflow/.local/lib/python3.8/site-packages/airflow/models/dagbag.py", line 344, in parse
    loader.exec_module(new_module)
  File "<frozen importlib._bootstrap_external>", line 843, in exec_module
  File "<frozen importlib._bootstrap>", line 219, in _call_with_frames_removed
  File "/opt/airflow/dags/star_wars_data_pipeline.py", line 14, in <module>
    from script_results import generate_results_json as generate_results_json
ModuleNotFoundError: No module named 'script_results'
[2024-02-13T18:58:46.769+0000] {processor.py:842} WARNING - No viable dags retrieved from /opt/airflow/dags/star_wars_data_pipeline.py
[2024-02-13T18:58:46.790+0000] {processor.py:183} INFO - Processing /opt/airflow/dags/star_wars_data_pipeline.py took 0.063 seconds
[2024-02-13T18:58:51.860+0000] {processor.py:161} INFO - Started process (PID=175) to work on /opt/airflow/dags/star_wars_data_pipeline.py
[2024-02-13T18:58:51.861+0000] {processor.py:830} INFO - Processing file /opt/airflow/dags/star_wars_data_pipeline.py for tasks to queue
[2024-02-13T18:58:51.864+0000] {logging_mixin.py:188} INFO - [2024-02-13T18:58:51.864+0000] {dagbag.py:538} INFO - Filling up the DagBag from /opt/airflow/dags/star_wars_data_pipeline.py
[2024-02-13T18:58:51.902+0000] {logging_mixin.py:188} INFO - [2024-02-13T18:58:51.898+0000] {dagbag.py:348} ERROR - Failed to import: /opt/airflow/dags/star_wars_data_pipeline.py
Traceback (most recent call last):
  File "/home/airflow/.local/lib/python3.8/site-packages/airflow/models/dagbag.py", line 344, in parse
    loader.exec_module(new_module)
  File "<frozen importlib._bootstrap_external>", line 843, in exec_module
  File "<frozen importlib._bootstrap>", line 219, in _call_with_frames_removed
  File "/opt/airflow/dags/star_wars_data_pipeline.py", line 14, in <module>
    from script_results import generate_results_json as generate_results_json
ModuleNotFoundError: No module named 'script_results'
[2024-02-13T18:58:51.903+0000] {processor.py:842} WARNING - No viable dags retrieved from /opt/airflow/dags/star_wars_data_pipeline.py
[2024-02-13T18:58:51.924+0000] {processor.py:183} INFO - Processing /opt/airflow/dags/star_wars_data_pipeline.py took 0.067 seconds
[2024-02-13T18:58:56.989+0000] {processor.py:161} INFO - Started process (PID=176) to work on /opt/airflow/dags/star_wars_data_pipeline.py
[2024-02-13T18:58:56.991+0000] {processor.py:830} INFO - Processing file /opt/airflow/dags/star_wars_data_pipeline.py for tasks to queue
[2024-02-13T18:58:56.992+0000] {logging_mixin.py:188} INFO - [2024-02-13T18:58:56.992+0000] {dagbag.py:538} INFO - Filling up the DagBag from /opt/airflow/dags/star_wars_data_pipeline.py
[2024-02-13T18:58:57.028+0000] {logging_mixin.py:188} INFO - [2024-02-13T18:58:57.024+0000] {dagbag.py:348} ERROR - Failed to import: /opt/airflow/dags/star_wars_data_pipeline.py
Traceback (most recent call last):
  File "/home/airflow/.local/lib/python3.8/site-packages/airflow/models/dagbag.py", line 344, in parse
    loader.exec_module(new_module)
  File "<frozen importlib._bootstrap_external>", line 843, in exec_module
  File "<frozen importlib._bootstrap>", line 219, in _call_with_frames_removed
  File "/opt/airflow/dags/star_wars_data_pipeline.py", line 14, in <module>
    from script_results import generate_results_json as generate_results_json
ModuleNotFoundError: No module named 'script_results'
[2024-02-13T18:58:57.029+0000] {processor.py:842} WARNING - No viable dags retrieved from /opt/airflow/dags/star_wars_data_pipeline.py
[2024-02-13T18:58:57.054+0000] {processor.py:183} INFO - Processing /opt/airflow/dags/star_wars_data_pipeline.py took 0.067 seconds
[2024-02-13T18:59:02.117+0000] {processor.py:161} INFO - Started process (PID=185) to work on /opt/airflow/dags/star_wars_data_pipeline.py
[2024-02-13T18:59:02.119+0000] {processor.py:830} INFO - Processing file /opt/airflow/dags/star_wars_data_pipeline.py for tasks to queue
[2024-02-13T18:59:02.121+0000] {logging_mixin.py:188} INFO - [2024-02-13T18:59:02.121+0000] {dagbag.py:538} INFO - Filling up the DagBag from /opt/airflow/dags/star_wars_data_pipeline.py
[2024-02-13T18:59:02.158+0000] {logging_mixin.py:188} INFO - [2024-02-13T18:59:02.154+0000] {dagbag.py:348} ERROR - Failed to import: /opt/airflow/dags/star_wars_data_pipeline.py
Traceback (most recent call last):
  File "/home/airflow/.local/lib/python3.8/site-packages/airflow/models/dagbag.py", line 344, in parse
    loader.exec_module(new_module)
  File "<frozen importlib._bootstrap_external>", line 843, in exec_module
  File "<frozen importlib._bootstrap>", line 219, in _call_with_frames_removed
  File "/opt/airflow/dags/star_wars_data_pipeline.py", line 14, in <module>
    from script_results import generate_results_json as generate_results_json
ModuleNotFoundError: No module named 'script_results'
[2024-02-13T18:59:02.160+0000] {processor.py:842} WARNING - No viable dags retrieved from /opt/airflow/dags/star_wars_data_pipeline.py
[2024-02-13T18:59:02.185+0000] {processor.py:183} INFO - Processing /opt/airflow/dags/star_wars_data_pipeline.py took 0.069 seconds
[2024-02-13T18:59:07.254+0000] {processor.py:161} INFO - Started process (PID=186) to work on /opt/airflow/dags/star_wars_data_pipeline.py
[2024-02-13T18:59:07.256+0000] {processor.py:830} INFO - Processing file /opt/airflow/dags/star_wars_data_pipeline.py for tasks to queue
[2024-02-13T18:59:07.258+0000] {logging_mixin.py:188} INFO - [2024-02-13T18:59:07.258+0000] {dagbag.py:538} INFO - Filling up the DagBag from /opt/airflow/dags/star_wars_data_pipeline.py
[2024-02-13T18:59:07.296+0000] {logging_mixin.py:188} INFO - [2024-02-13T18:59:07.293+0000] {dagbag.py:348} ERROR - Failed to import: /opt/airflow/dags/star_wars_data_pipeline.py
Traceback (most recent call last):
  File "/home/airflow/.local/lib/python3.8/site-packages/airflow/models/dagbag.py", line 344, in parse
    loader.exec_module(new_module)
  File "<frozen importlib._bootstrap_external>", line 843, in exec_module
  File "<frozen importlib._bootstrap>", line 219, in _call_with_frames_removed
  File "/opt/airflow/dags/star_wars_data_pipeline.py", line 14, in <module>
    from script_results import generate_results_json as generate_results_json
ModuleNotFoundError: No module named 'script_results'
[2024-02-13T18:59:07.298+0000] {processor.py:842} WARNING - No viable dags retrieved from /opt/airflow/dags/star_wars_data_pipeline.py
[2024-02-13T18:59:07.323+0000] {processor.py:183} INFO - Processing /opt/airflow/dags/star_wars_data_pipeline.py took 0.071 seconds
[2024-02-13T18:59:12.394+0000] {processor.py:161} INFO - Started process (PID=195) to work on /opt/airflow/dags/star_wars_data_pipeline.py
[2024-02-13T18:59:12.395+0000] {processor.py:830} INFO - Processing file /opt/airflow/dags/star_wars_data_pipeline.py for tasks to queue
[2024-02-13T18:59:12.398+0000] {logging_mixin.py:188} INFO - [2024-02-13T18:59:12.397+0000] {dagbag.py:538} INFO - Filling up the DagBag from /opt/airflow/dags/star_wars_data_pipeline.py
[2024-02-13T18:59:12.438+0000] {logging_mixin.py:188} INFO - [2024-02-13T18:59:12.433+0000] {dagbag.py:348} ERROR - Failed to import: /opt/airflow/dags/star_wars_data_pipeline.py
Traceback (most recent call last):
  File "/home/airflow/.local/lib/python3.8/site-packages/airflow/models/dagbag.py", line 344, in parse
    loader.exec_module(new_module)
  File "<frozen importlib._bootstrap_external>", line 843, in exec_module
  File "<frozen importlib._bootstrap>", line 219, in _call_with_frames_removed
  File "/opt/airflow/dags/star_wars_data_pipeline.py", line 14, in <module>
    from script_results import generate_results_json as generate_results_json
ModuleNotFoundError: No module named 'script_results'
[2024-02-13T18:59:12.440+0000] {processor.py:842} WARNING - No viable dags retrieved from /opt/airflow/dags/star_wars_data_pipeline.py
[2024-02-13T18:59:12.463+0000] {processor.py:183} INFO - Processing /opt/airflow/dags/star_wars_data_pipeline.py took 0.071 seconds
[2024-02-13T18:59:17.526+0000] {processor.py:161} INFO - Started process (PID=196) to work on /opt/airflow/dags/star_wars_data_pipeline.py
[2024-02-13T18:59:17.528+0000] {processor.py:830} INFO - Processing file /opt/airflow/dags/star_wars_data_pipeline.py for tasks to queue
[2024-02-13T18:59:17.530+0000] {logging_mixin.py:188} INFO - [2024-02-13T18:59:17.529+0000] {dagbag.py:538} INFO - Filling up the DagBag from /opt/airflow/dags/star_wars_data_pipeline.py
[2024-02-13T18:59:17.563+0000] {logging_mixin.py:188} INFO - [2024-02-13T18:59:17.560+0000] {dagbag.py:348} ERROR - Failed to import: /opt/airflow/dags/star_wars_data_pipeline.py
Traceback (most recent call last):
  File "/home/airflow/.local/lib/python3.8/site-packages/airflow/models/dagbag.py", line 344, in parse
    loader.exec_module(new_module)
  File "<frozen importlib._bootstrap_external>", line 843, in exec_module
  File "<frozen importlib._bootstrap>", line 219, in _call_with_frames_removed
  File "/opt/airflow/dags/star_wars_data_pipeline.py", line 14, in <module>
    from script_results import generate_results_json as generate_results_json
ModuleNotFoundError: No module named 'script_results'
[2024-02-13T18:59:17.565+0000] {processor.py:842} WARNING - No viable dags retrieved from /opt/airflow/dags/star_wars_data_pipeline.py
[2024-02-13T18:59:17.592+0000] {processor.py:183} INFO - Processing /opt/airflow/dags/star_wars_data_pipeline.py took 0.068 seconds
[2024-02-13T18:59:22.643+0000] {processor.py:161} INFO - Started process (PID=197) to work on /opt/airflow/dags/star_wars_data_pipeline.py
[2024-02-13T18:59:22.644+0000] {processor.py:830} INFO - Processing file /opt/airflow/dags/star_wars_data_pipeline.py for tasks to queue
[2024-02-13T18:59:22.646+0000] {logging_mixin.py:188} INFO - [2024-02-13T18:59:22.646+0000] {dagbag.py:538} INFO - Filling up the DagBag from /opt/airflow/dags/star_wars_data_pipeline.py
[2024-02-13T18:59:22.678+0000] {logging_mixin.py:188} INFO - [2024-02-13T18:59:22.675+0000] {dagbag.py:348} ERROR - Failed to import: /opt/airflow/dags/star_wars_data_pipeline.py
Traceback (most recent call last):
  File "/home/airflow/.local/lib/python3.8/site-packages/airflow/models/dagbag.py", line 344, in parse
    loader.exec_module(new_module)
  File "<frozen importlib._bootstrap_external>", line 843, in exec_module
  File "<frozen importlib._bootstrap>", line 219, in _call_with_frames_removed
  File "/opt/airflow/dags/star_wars_data_pipeline.py", line 14, in <module>
    from script_results import generate_results_json as generate_results_json
ModuleNotFoundError: No module named 'script_results'
[2024-02-13T18:59:22.680+0000] {processor.py:842} WARNING - No viable dags retrieved from /opt/airflow/dags/star_wars_data_pipeline.py
[2024-02-13T18:59:22.702+0000] {processor.py:183} INFO - Processing /opt/airflow/dags/star_wars_data_pipeline.py took 0.062 seconds
[2024-02-13T18:59:27.770+0000] {processor.py:161} INFO - Started process (PID=206) to work on /opt/airflow/dags/star_wars_data_pipeline.py
[2024-02-13T18:59:27.771+0000] {processor.py:830} INFO - Processing file /opt/airflow/dags/star_wars_data_pipeline.py for tasks to queue
[2024-02-13T18:59:27.774+0000] {logging_mixin.py:188} INFO - [2024-02-13T18:59:27.774+0000] {dagbag.py:538} INFO - Filling up the DagBag from /opt/airflow/dags/star_wars_data_pipeline.py
[2024-02-13T18:59:27.816+0000] {logging_mixin.py:188} INFO - [2024-02-13T18:59:27.811+0000] {dagbag.py:348} ERROR - Failed to import: /opt/airflow/dags/star_wars_data_pipeline.py
Traceback (most recent call last):
  File "/home/airflow/.local/lib/python3.8/site-packages/airflow/models/dagbag.py", line 344, in parse
    loader.exec_module(new_module)
  File "<frozen importlib._bootstrap_external>", line 843, in exec_module
  File "<frozen importlib._bootstrap>", line 219, in _call_with_frames_removed
  File "/opt/airflow/dags/star_wars_data_pipeline.py", line 14, in <module>
    from script_results import generate_results_json as generate_results_json
ModuleNotFoundError: No module named 'script_results'
[2024-02-13T18:59:27.817+0000] {processor.py:842} WARNING - No viable dags retrieved from /opt/airflow/dags/star_wars_data_pipeline.py
[2024-02-13T18:59:27.842+0000] {processor.py:183} INFO - Processing /opt/airflow/dags/star_wars_data_pipeline.py took 0.074 seconds
[2024-02-13T18:59:32.907+0000] {processor.py:161} INFO - Started process (PID=207) to work on /opt/airflow/dags/star_wars_data_pipeline.py
[2024-02-13T18:59:32.908+0000] {processor.py:830} INFO - Processing file /opt/airflow/dags/star_wars_data_pipeline.py for tasks to queue
[2024-02-13T18:59:32.911+0000] {logging_mixin.py:188} INFO - [2024-02-13T18:59:32.910+0000] {dagbag.py:538} INFO - Filling up the DagBag from /opt/airflow/dags/star_wars_data_pipeline.py
[2024-02-13T18:59:32.945+0000] {logging_mixin.py:188} INFO - [2024-02-13T18:59:32.942+0000] {dagbag.py:348} ERROR - Failed to import: /opt/airflow/dags/star_wars_data_pipeline.py
Traceback (most recent call last):
  File "/home/airflow/.local/lib/python3.8/site-packages/airflow/models/dagbag.py", line 344, in parse
    loader.exec_module(new_module)
  File "<frozen importlib._bootstrap_external>", line 843, in exec_module
  File "<frozen importlib._bootstrap>", line 219, in _call_with_frames_removed
  File "/opt/airflow/dags/star_wars_data_pipeline.py", line 14, in <module>
    from script_results import generate_results_json as generate_results_json
ModuleNotFoundError: No module named 'script_results'
[2024-02-13T18:59:32.947+0000] {processor.py:842} WARNING - No viable dags retrieved from /opt/airflow/dags/star_wars_data_pipeline.py
[2024-02-13T18:59:32.972+0000] {processor.py:183} INFO - Processing /opt/airflow/dags/star_wars_data_pipeline.py took 0.068 seconds
[2024-02-13T18:59:38.050+0000] {processor.py:161} INFO - Started process (PID=216) to work on /opt/airflow/dags/star_wars_data_pipeline.py
[2024-02-13T18:59:38.052+0000] {processor.py:830} INFO - Processing file /opt/airflow/dags/star_wars_data_pipeline.py for tasks to queue
[2024-02-13T18:59:38.054+0000] {logging_mixin.py:188} INFO - [2024-02-13T18:59:38.054+0000] {dagbag.py:538} INFO - Filling up the DagBag from /opt/airflow/dags/star_wars_data_pipeline.py
[2024-02-13T18:59:38.103+0000] {logging_mixin.py:188} INFO - [2024-02-13T18:59:38.097+0000] {dagbag.py:348} ERROR - Failed to import: /opt/airflow/dags/star_wars_data_pipeline.py
Traceback (most recent call last):
  File "/home/airflow/.local/lib/python3.8/site-packages/airflow/models/dagbag.py", line 344, in parse
    loader.exec_module(new_module)
  File "<frozen importlib._bootstrap_external>", line 843, in exec_module
  File "<frozen importlib._bootstrap>", line 219, in _call_with_frames_removed
  File "/opt/airflow/dags/star_wars_data_pipeline.py", line 14, in <module>
    from script_results import generate_results_json as generate_results_json
ModuleNotFoundError: No module named 'script_results'
[2024-02-13T18:59:38.104+0000] {processor.py:842} WARNING - No viable dags retrieved from /opt/airflow/dags/star_wars_data_pipeline.py
[2024-02-13T18:59:38.130+0000] {processor.py:183} INFO - Processing /opt/airflow/dags/star_wars_data_pipeline.py took 0.084 seconds
[2024-02-13T18:59:43.199+0000] {processor.py:161} INFO - Started process (PID=217) to work on /opt/airflow/dags/star_wars_data_pipeline.py
[2024-02-13T18:59:43.200+0000] {processor.py:830} INFO - Processing file /opt/airflow/dags/star_wars_data_pipeline.py for tasks to queue
[2024-02-13T18:59:43.203+0000] {logging_mixin.py:188} INFO - [2024-02-13T18:59:43.203+0000] {dagbag.py:538} INFO - Filling up the DagBag from /opt/airflow/dags/star_wars_data_pipeline.py
[2024-02-13T18:59:43.240+0000] {logging_mixin.py:188} INFO - [2024-02-13T18:59:43.235+0000] {dagbag.py:348} ERROR - Failed to import: /opt/airflow/dags/star_wars_data_pipeline.py
Traceback (most recent call last):
  File "/home/airflow/.local/lib/python3.8/site-packages/airflow/models/dagbag.py", line 344, in parse
    loader.exec_module(new_module)
  File "<frozen importlib._bootstrap_external>", line 843, in exec_module
  File "<frozen importlib._bootstrap>", line 219, in _call_with_frames_removed
  File "/opt/airflow/dags/star_wars_data_pipeline.py", line 14, in <module>
    from script_results import generate_results_json as generate_results_json
ModuleNotFoundError: No module named 'script_results'
[2024-02-13T18:59:43.241+0000] {processor.py:842} WARNING - No viable dags retrieved from /opt/airflow/dags/star_wars_data_pipeline.py
[2024-02-13T18:59:43.264+0000] {processor.py:183} INFO - Processing /opt/airflow/dags/star_wars_data_pipeline.py took 0.068 seconds
[2024-02-13T18:59:48.331+0000] {processor.py:161} INFO - Started process (PID=218) to work on /opt/airflow/dags/star_wars_data_pipeline.py
[2024-02-13T18:59:48.332+0000] {processor.py:830} INFO - Processing file /opt/airflow/dags/star_wars_data_pipeline.py for tasks to queue
[2024-02-13T18:59:48.334+0000] {logging_mixin.py:188} INFO - [2024-02-13T18:59:48.334+0000] {dagbag.py:538} INFO - Filling up the DagBag from /opt/airflow/dags/star_wars_data_pipeline.py
[2024-02-13T18:59:48.374+0000] {logging_mixin.py:188} INFO - [2024-02-13T18:59:48.370+0000] {dagbag.py:348} ERROR - Failed to import: /opt/airflow/dags/star_wars_data_pipeline.py
Traceback (most recent call last):
  File "/home/airflow/.local/lib/python3.8/site-packages/airflow/models/dagbag.py", line 344, in parse
    loader.exec_module(new_module)
  File "<frozen importlib._bootstrap_external>", line 843, in exec_module
  File "<frozen importlib._bootstrap>", line 219, in _call_with_frames_removed
  File "/opt/airflow/dags/star_wars_data_pipeline.py", line 14, in <module>
    from script_results import generate_results_json as generate_results_json
ModuleNotFoundError: No module named 'script_results'
[2024-02-13T18:59:48.376+0000] {processor.py:842} WARNING - No viable dags retrieved from /opt/airflow/dags/star_wars_data_pipeline.py
[2024-02-13T18:59:48.405+0000] {processor.py:183} INFO - Processing /opt/airflow/dags/star_wars_data_pipeline.py took 0.077 seconds
[2024-02-13T18:59:53.479+0000] {processor.py:161} INFO - Started process (PID=227) to work on /opt/airflow/dags/star_wars_data_pipeline.py
[2024-02-13T18:59:53.480+0000] {processor.py:830} INFO - Processing file /opt/airflow/dags/star_wars_data_pipeline.py for tasks to queue
[2024-02-13T18:59:53.483+0000] {logging_mixin.py:188} INFO - [2024-02-13T18:59:53.482+0000] {dagbag.py:538} INFO - Filling up the DagBag from /opt/airflow/dags/star_wars_data_pipeline.py
[2024-02-13T18:59:53.516+0000] {logging_mixin.py:188} INFO - [2024-02-13T18:59:53.511+0000] {dagbag.py:348} ERROR - Failed to import: /opt/airflow/dags/star_wars_data_pipeline.py
Traceback (most recent call last):
  File "/home/airflow/.local/lib/python3.8/site-packages/airflow/models/dagbag.py", line 344, in parse
    loader.exec_module(new_module)
  File "<frozen importlib._bootstrap_external>", line 843, in exec_module
  File "<frozen importlib._bootstrap>", line 219, in _call_with_frames_removed
  File "/opt/airflow/dags/star_wars_data_pipeline.py", line 14, in <module>
    from script_results import generate_results_json as generate_results_json
ModuleNotFoundError: No module named 'script_results'
[2024-02-13T18:59:53.518+0000] {processor.py:842} WARNING - No viable dags retrieved from /opt/airflow/dags/star_wars_data_pipeline.py
[2024-02-13T18:59:53.537+0000] {processor.py:183} INFO - Processing /opt/airflow/dags/star_wars_data_pipeline.py took 0.061 seconds
[2024-02-13T18:59:58.610+0000] {processor.py:161} INFO - Started process (PID=228) to work on /opt/airflow/dags/star_wars_data_pipeline.py
[2024-02-13T18:59:58.612+0000] {processor.py:830} INFO - Processing file /opt/airflow/dags/star_wars_data_pipeline.py for tasks to queue
[2024-02-13T18:59:58.614+0000] {logging_mixin.py:188} INFO - [2024-02-13T18:59:58.613+0000] {dagbag.py:538} INFO - Filling up the DagBag from /opt/airflow/dags/star_wars_data_pipeline.py
[2024-02-13T18:59:58.649+0000] {logging_mixin.py:188} INFO - [2024-02-13T18:59:58.644+0000] {dagbag.py:348} ERROR - Failed to import: /opt/airflow/dags/star_wars_data_pipeline.py
Traceback (most recent call last):
  File "/home/airflow/.local/lib/python3.8/site-packages/airflow/models/dagbag.py", line 344, in parse
    loader.exec_module(new_module)
  File "<frozen importlib._bootstrap_external>", line 843, in exec_module
  File "<frozen importlib._bootstrap>", line 219, in _call_with_frames_removed
  File "/opt/airflow/dags/star_wars_data_pipeline.py", line 14, in <module>
    from script_results import generate_results_json as generate_results_json
ModuleNotFoundError: No module named 'script_results'
[2024-02-13T18:59:58.651+0000] {processor.py:842} WARNING - No viable dags retrieved from /opt/airflow/dags/star_wars_data_pipeline.py
[2024-02-13T18:59:58.673+0000] {processor.py:183} INFO - Processing /opt/airflow/dags/star_wars_data_pipeline.py took 0.065 seconds
[2024-02-13T19:00:03.719+0000] {processor.py:161} INFO - Started process (PID=237) to work on /opt/airflow/dags/star_wars_data_pipeline.py
[2024-02-13T19:00:03.722+0000] {processor.py:830} INFO - Processing file /opt/airflow/dags/star_wars_data_pipeline.py for tasks to queue
[2024-02-13T19:00:03.723+0000] {logging_mixin.py:188} INFO - [2024-02-13T19:00:03.723+0000] {dagbag.py:538} INFO - Filling up the DagBag from /opt/airflow/dags/star_wars_data_pipeline.py
[2024-02-13T19:00:03.771+0000] {logging_mixin.py:188} INFO - [2024-02-13T19:00:03.765+0000] {dagbag.py:348} ERROR - Failed to import: /opt/airflow/dags/star_wars_data_pipeline.py
Traceback (most recent call last):
  File "/home/airflow/.local/lib/python3.8/site-packages/airflow/models/dagbag.py", line 344, in parse
    loader.exec_module(new_module)
  File "<frozen importlib._bootstrap_external>", line 843, in exec_module
  File "<frozen importlib._bootstrap>", line 219, in _call_with_frames_removed
  File "/opt/airflow/dags/star_wars_data_pipeline.py", line 14, in <module>
    from script_results import generate_results_json as generate_results_json
ModuleNotFoundError: No module named 'script_results'
[2024-02-13T19:00:03.773+0000] {processor.py:842} WARNING - No viable dags retrieved from /opt/airflow/dags/star_wars_data_pipeline.py
[2024-02-13T19:00:03.800+0000] {processor.py:183} INFO - Processing /opt/airflow/dags/star_wars_data_pipeline.py took 0.083 seconds
[2024-02-13T19:00:08.877+0000] {processor.py:161} INFO - Started process (PID=238) to work on /opt/airflow/dags/star_wars_data_pipeline.py
[2024-02-13T19:00:08.878+0000] {processor.py:830} INFO - Processing file /opt/airflow/dags/star_wars_data_pipeline.py for tasks to queue
[2024-02-13T19:00:08.881+0000] {logging_mixin.py:188} INFO - [2024-02-13T19:00:08.880+0000] {dagbag.py:538} INFO - Filling up the DagBag from /opt/airflow/dags/star_wars_data_pipeline.py
[2024-02-13T19:00:08.924+0000] {logging_mixin.py:188} INFO - [2024-02-13T19:00:08.919+0000] {dagbag.py:348} ERROR - Failed to import: /opt/airflow/dags/star_wars_data_pipeline.py
Traceback (most recent call last):
  File "/home/airflow/.local/lib/python3.8/site-packages/airflow/models/dagbag.py", line 344, in parse
    loader.exec_module(new_module)
  File "<frozen importlib._bootstrap_external>", line 843, in exec_module
  File "<frozen importlib._bootstrap>", line 219, in _call_with_frames_removed
  File "/opt/airflow/dags/star_wars_data_pipeline.py", line 14, in <module>
    from script_results import generate_results_json as generate_results_json
ModuleNotFoundError: No module named 'script_results'
[2024-02-13T19:00:08.925+0000] {processor.py:842} WARNING - No viable dags retrieved from /opt/airflow/dags/star_wars_data_pipeline.py
[2024-02-13T19:00:08.951+0000] {processor.py:183} INFO - Processing /opt/airflow/dags/star_wars_data_pipeline.py took 0.076 seconds
[2024-02-13T19:00:14.028+0000] {processor.py:161} INFO - Started process (PID=239) to work on /opt/airflow/dags/star_wars_data_pipeline.py
[2024-02-13T19:00:14.030+0000] {processor.py:830} INFO - Processing file /opt/airflow/dags/star_wars_data_pipeline.py for tasks to queue
[2024-02-13T19:00:14.032+0000] {logging_mixin.py:188} INFO - [2024-02-13T19:00:14.032+0000] {dagbag.py:538} INFO - Filling up the DagBag from /opt/airflow/dags/star_wars_data_pipeline.py
[2024-02-13T19:00:14.068+0000] {logging_mixin.py:188} INFO - [2024-02-13T19:00:14.063+0000] {dagbag.py:348} ERROR - Failed to import: /opt/airflow/dags/star_wars_data_pipeline.py
Traceback (most recent call last):
  File "/home/airflow/.local/lib/python3.8/site-packages/airflow/models/dagbag.py", line 344, in parse
    loader.exec_module(new_module)
  File "<frozen importlib._bootstrap_external>", line 843, in exec_module
  File "<frozen importlib._bootstrap>", line 219, in _call_with_frames_removed
  File "/opt/airflow/dags/star_wars_data_pipeline.py", line 14, in <module>
    from script_results import generate_results_json as generate_results_json
ModuleNotFoundError: No module named 'script_results'
[2024-02-13T19:00:14.070+0000] {processor.py:842} WARNING - No viable dags retrieved from /opt/airflow/dags/star_wars_data_pipeline.py
[2024-02-13T19:00:14.091+0000] {processor.py:183} INFO - Processing /opt/airflow/dags/star_wars_data_pipeline.py took 0.065 seconds
[2024-02-13T19:00:19.164+0000] {processor.py:161} INFO - Started process (PID=248) to work on /opt/airflow/dags/star_wars_data_pipeline.py
[2024-02-13T19:00:19.165+0000] {processor.py:830} INFO - Processing file /opt/airflow/dags/star_wars_data_pipeline.py for tasks to queue
[2024-02-13T19:00:19.168+0000] {logging_mixin.py:188} INFO - [2024-02-13T19:00:19.168+0000] {dagbag.py:538} INFO - Filling up the DagBag from /opt/airflow/dags/star_wars_data_pipeline.py
[2024-02-13T19:00:19.213+0000] {logging_mixin.py:188} INFO - [2024-02-13T19:00:19.209+0000] {dagbag.py:348} ERROR - Failed to import: /opt/airflow/dags/star_wars_data_pipeline.py
Traceback (most recent call last):
  File "/home/airflow/.local/lib/python3.8/site-packages/airflow/models/dagbag.py", line 344, in parse
    loader.exec_module(new_module)
  File "<frozen importlib._bootstrap_external>", line 843, in exec_module
  File "<frozen importlib._bootstrap>", line 219, in _call_with_frames_removed
  File "/opt/airflow/dags/star_wars_data_pipeline.py", line 14, in <module>
    from script_results import generate_results_json as generate_results_json
ModuleNotFoundError: No module named 'script_results'
[2024-02-13T19:00:19.215+0000] {processor.py:842} WARNING - No viable dags retrieved from /opt/airflow/dags/star_wars_data_pipeline.py
[2024-02-13T19:00:19.235+0000] {processor.py:183} INFO - Processing /opt/airflow/dags/star_wars_data_pipeline.py took 0.074 seconds
[2024-02-13T19:00:24.297+0000] {processor.py:161} INFO - Started process (PID=249) to work on /opt/airflow/dags/star_wars_data_pipeline.py
[2024-02-13T19:00:24.299+0000] {processor.py:830} INFO - Processing file /opt/airflow/dags/star_wars_data_pipeline.py for tasks to queue
[2024-02-13T19:00:24.301+0000] {logging_mixin.py:188} INFO - [2024-02-13T19:00:24.301+0000] {dagbag.py:538} INFO - Filling up the DagBag from /opt/airflow/dags/star_wars_data_pipeline.py
[2024-02-13T19:00:24.344+0000] {logging_mixin.py:188} INFO - [2024-02-13T19:00:24.340+0000] {dagbag.py:348} ERROR - Failed to import: /opt/airflow/dags/star_wars_data_pipeline.py
Traceback (most recent call last):
  File "/home/airflow/.local/lib/python3.8/site-packages/airflow/models/dagbag.py", line 344, in parse
    loader.exec_module(new_module)
  File "<frozen importlib._bootstrap_external>", line 843, in exec_module
  File "<frozen importlib._bootstrap>", line 219, in _call_with_frames_removed
  File "/opt/airflow/dags/star_wars_data_pipeline.py", line 14, in <module>
    from script_results import generate_results_json as generate_results_json
ModuleNotFoundError: No module named 'script_results'
[2024-02-13T19:00:24.345+0000] {processor.py:842} WARNING - No viable dags retrieved from /opt/airflow/dags/star_wars_data_pipeline.py
[2024-02-13T19:00:24.408+0000] {processor.py:183} INFO - Processing /opt/airflow/dags/star_wars_data_pipeline.py took 0.115 seconds
[2024-02-13T19:00:29.486+0000] {processor.py:161} INFO - Started process (PID=258) to work on /opt/airflow/dags/star_wars_data_pipeline.py
[2024-02-13T19:00:29.487+0000] {processor.py:830} INFO - Processing file /opt/airflow/dags/star_wars_data_pipeline.py for tasks to queue
[2024-02-13T19:00:29.490+0000] {logging_mixin.py:188} INFO - [2024-02-13T19:00:29.489+0000] {dagbag.py:538} INFO - Filling up the DagBag from /opt/airflow/dags/star_wars_data_pipeline.py
[2024-02-13T19:00:29.537+0000] {logging_mixin.py:188} INFO - [2024-02-13T19:00:29.531+0000] {dagbag.py:348} ERROR - Failed to import: /opt/airflow/dags/star_wars_data_pipeline.py
Traceback (most recent call last):
  File "/home/airflow/.local/lib/python3.8/site-packages/airflow/models/dagbag.py", line 344, in parse
    loader.exec_module(new_module)
  File "<frozen importlib._bootstrap_external>", line 843, in exec_module
  File "<frozen importlib._bootstrap>", line 219, in _call_with_frames_removed
  File "/opt/airflow/dags/star_wars_data_pipeline.py", line 14, in <module>
    from script_results import generate_results_json as generate_results_json
ModuleNotFoundError: No module named 'script_results'
[2024-02-13T19:00:29.540+0000] {processor.py:842} WARNING - No viable dags retrieved from /opt/airflow/dags/star_wars_data_pipeline.py
[2024-02-13T19:00:29.657+0000] {processor.py:183} INFO - Processing /opt/airflow/dags/star_wars_data_pipeline.py took 0.175 seconds
[2024-02-13T19:00:34.751+0000] {processor.py:161} INFO - Started process (PID=259) to work on /opt/airflow/dags/star_wars_data_pipeline.py
[2024-02-13T19:00:34.752+0000] {processor.py:830} INFO - Processing file /opt/airflow/dags/star_wars_data_pipeline.py for tasks to queue
[2024-02-13T19:00:34.755+0000] {logging_mixin.py:188} INFO - [2024-02-13T19:00:34.755+0000] {dagbag.py:538} INFO - Filling up the DagBag from /opt/airflow/dags/star_wars_data_pipeline.py
[2024-02-13T19:00:34.802+0000] {logging_mixin.py:188} INFO - [2024-02-13T19:00:34.797+0000] {dagbag.py:348} ERROR - Failed to import: /opt/airflow/dags/star_wars_data_pipeline.py
Traceback (most recent call last):
  File "/home/airflow/.local/lib/python3.8/site-packages/airflow/models/dagbag.py", line 344, in parse
    loader.exec_module(new_module)
  File "<frozen importlib._bootstrap_external>", line 843, in exec_module
  File "<frozen importlib._bootstrap>", line 219, in _call_with_frames_removed
  File "/opt/airflow/dags/star_wars_data_pipeline.py", line 14, in <module>
    from script_results import generate_results_json as generate_results_json
ModuleNotFoundError: No module named 'script_results'
[2024-02-13T19:00:34.804+0000] {processor.py:842} WARNING - No viable dags retrieved from /opt/airflow/dags/star_wars_data_pipeline.py
[2024-02-13T19:00:34.829+0000] {processor.py:183} INFO - Processing /opt/airflow/dags/star_wars_data_pipeline.py took 0.085 seconds
[2024-02-13T19:00:39.918+0000] {processor.py:161} INFO - Started process (PID=267) to work on /opt/airflow/dags/star_wars_data_pipeline.py
[2024-02-13T19:00:39.920+0000] {processor.py:830} INFO - Processing file /opt/airflow/dags/star_wars_data_pipeline.py for tasks to queue
[2024-02-13T19:00:39.924+0000] {logging_mixin.py:188} INFO - [2024-02-13T19:00:39.924+0000] {dagbag.py:538} INFO - Filling up the DagBag from /opt/airflow/dags/star_wars_data_pipeline.py
[2024-02-13T19:00:39.971+0000] {logging_mixin.py:188} INFO - [2024-02-13T19:00:39.966+0000] {dagbag.py:348} ERROR - Failed to import: /opt/airflow/dags/star_wars_data_pipeline.py
Traceback (most recent call last):
  File "/home/airflow/.local/lib/python3.8/site-packages/airflow/models/dagbag.py", line 344, in parse
    loader.exec_module(new_module)
  File "<frozen importlib._bootstrap_external>", line 843, in exec_module
  File "<frozen importlib._bootstrap>", line 219, in _call_with_frames_removed
  File "/opt/airflow/dags/star_wars_data_pipeline.py", line 14, in <module>
    from script_results import generate_results_json as generate_results_json
ModuleNotFoundError: No module named 'script_results'
[2024-02-13T19:00:39.974+0000] {processor.py:842} WARNING - No viable dags retrieved from /opt/airflow/dags/star_wars_data_pipeline.py
[2024-02-13T19:00:40.007+0000] {processor.py:183} INFO - Processing /opt/airflow/dags/star_wars_data_pipeline.py took 0.094 seconds
[2024-02-13T19:00:45.077+0000] {processor.py:161} INFO - Started process (PID=269) to work on /opt/airflow/dags/star_wars_data_pipeline.py
[2024-02-13T19:00:45.079+0000] {processor.py:830} INFO - Processing file /opt/airflow/dags/star_wars_data_pipeline.py for tasks to queue
[2024-02-13T19:00:45.082+0000] {logging_mixin.py:188} INFO - [2024-02-13T19:00:45.081+0000] {dagbag.py:538} INFO - Filling up the DagBag from /opt/airflow/dags/star_wars_data_pipeline.py
[2024-02-13T19:00:45.134+0000] {logging_mixin.py:188} INFO - [2024-02-13T19:00:45.128+0000] {dagbag.py:348} ERROR - Failed to import: /opt/airflow/dags/star_wars_data_pipeline.py
Traceback (most recent call last):
  File "/home/airflow/.local/lib/python3.8/site-packages/airflow/models/dagbag.py", line 344, in parse
    loader.exec_module(new_module)
  File "<frozen importlib._bootstrap_external>", line 843, in exec_module
  File "<frozen importlib._bootstrap>", line 219, in _call_with_frames_removed
  File "/opt/airflow/dags/star_wars_data_pipeline.py", line 14, in <module>
    from script_results import generate_results_json as generate_results_json
ModuleNotFoundError: No module named 'script_results'
[2024-02-13T19:00:45.137+0000] {processor.py:842} WARNING - No viable dags retrieved from /opt/airflow/dags/star_wars_data_pipeline.py
[2024-02-13T19:00:45.170+0000] {processor.py:183} INFO - Processing /opt/airflow/dags/star_wars_data_pipeline.py took 0.096 seconds
[2024-02-13T19:00:50.256+0000] {processor.py:161} INFO - Started process (PID=270) to work on /opt/airflow/dags/star_wars_data_pipeline.py
[2024-02-13T19:00:50.257+0000] {processor.py:830} INFO - Processing file /opt/airflow/dags/star_wars_data_pipeline.py for tasks to queue
[2024-02-13T19:00:50.260+0000] {logging_mixin.py:188} INFO - [2024-02-13T19:00:50.260+0000] {dagbag.py:538} INFO - Filling up the DagBag from /opt/airflow/dags/star_wars_data_pipeline.py
[2024-02-13T19:00:50.310+0000] {logging_mixin.py:188} INFO - [2024-02-13T19:00:50.302+0000] {dagbag.py:348} ERROR - Failed to import: /opt/airflow/dags/star_wars_data_pipeline.py
Traceback (most recent call last):
  File "/home/airflow/.local/lib/python3.8/site-packages/airflow/models/dagbag.py", line 344, in parse
    loader.exec_module(new_module)
  File "<frozen importlib._bootstrap_external>", line 843, in exec_module
  File "<frozen importlib._bootstrap>", line 219, in _call_with_frames_removed
  File "/opt/airflow/dags/star_wars_data_pipeline.py", line 14, in <module>
    from script_results import generate_results_json as generate_results_json
ModuleNotFoundError: No module named 'script_results'
[2024-02-13T19:00:50.312+0000] {processor.py:842} WARNING - No viable dags retrieved from /opt/airflow/dags/star_wars_data_pipeline.py
[2024-02-13T19:00:50.343+0000] {processor.py:183} INFO - Processing /opt/airflow/dags/star_wars_data_pipeline.py took 0.090 seconds
[2024-02-13T19:00:55.430+0000] {processor.py:161} INFO - Started process (PID=279) to work on /opt/airflow/dags/star_wars_data_pipeline.py
[2024-02-13T19:00:55.432+0000] {processor.py:830} INFO - Processing file /opt/airflow/dags/star_wars_data_pipeline.py for tasks to queue
[2024-02-13T19:00:55.434+0000] {logging_mixin.py:188} INFO - [2024-02-13T19:00:55.434+0000] {dagbag.py:538} INFO - Filling up the DagBag from /opt/airflow/dags/star_wars_data_pipeline.py
[2024-02-13T19:00:55.485+0000] {logging_mixin.py:188} INFO - [2024-02-13T19:00:55.479+0000] {dagbag.py:348} ERROR - Failed to import: /opt/airflow/dags/star_wars_data_pipeline.py
Traceback (most recent call last):
  File "/home/airflow/.local/lib/python3.8/site-packages/airflow/models/dagbag.py", line 344, in parse
    loader.exec_module(new_module)
  File "<frozen importlib._bootstrap_external>", line 843, in exec_module
  File "<frozen importlib._bootstrap>", line 219, in _call_with_frames_removed
  File "/opt/airflow/dags/star_wars_data_pipeline.py", line 14, in <module>
    from script_results import generate_results_json as generate_results_json
ModuleNotFoundError: No module named 'script_results'
[2024-02-13T19:00:55.488+0000] {processor.py:842} WARNING - No viable dags retrieved from /opt/airflow/dags/star_wars_data_pipeline.py
[2024-02-13T19:00:55.518+0000] {processor.py:183} INFO - Processing /opt/airflow/dags/star_wars_data_pipeline.py took 0.093 seconds
[2024-02-13T19:01:00.604+0000] {processor.py:161} INFO - Started process (PID=280) to work on /opt/airflow/dags/star_wars_data_pipeline.py
[2024-02-13T19:01:00.606+0000] {processor.py:830} INFO - Processing file /opt/airflow/dags/star_wars_data_pipeline.py for tasks to queue
[2024-02-13T19:01:00.608+0000] {logging_mixin.py:188} INFO - [2024-02-13T19:01:00.608+0000] {dagbag.py:538} INFO - Filling up the DagBag from /opt/airflow/dags/star_wars_data_pipeline.py
[2024-02-13T19:01:00.653+0000] {logging_mixin.py:188} INFO - [2024-02-13T19:01:00.648+0000] {dagbag.py:348} ERROR - Failed to import: /opt/airflow/dags/star_wars_data_pipeline.py
Traceback (most recent call last):
  File "/home/airflow/.local/lib/python3.8/site-packages/airflow/models/dagbag.py", line 344, in parse
    loader.exec_module(new_module)
  File "<frozen importlib._bootstrap_external>", line 843, in exec_module
  File "<frozen importlib._bootstrap>", line 219, in _call_with_frames_removed
  File "/opt/airflow/dags/star_wars_data_pipeline.py", line 14, in <module>
    from script_results import generate_results_json as generate_results_json
ModuleNotFoundError: No module named 'script_results'
[2024-02-13T19:01:00.656+0000] {processor.py:842} WARNING - No viable dags retrieved from /opt/airflow/dags/star_wars_data_pipeline.py
[2024-02-13T19:01:00.682+0000] {processor.py:183} INFO - Processing /opt/airflow/dags/star_wars_data_pipeline.py took 0.082 seconds
[2024-02-13T19:01:05.787+0000] {processor.py:161} INFO - Started process (PID=281) to work on /opt/airflow/dags/star_wars_data_pipeline.py
[2024-02-13T19:01:05.789+0000] {processor.py:830} INFO - Processing file /opt/airflow/dags/star_wars_data_pipeline.py for tasks to queue
[2024-02-13T19:01:05.792+0000] {logging_mixin.py:188} INFO - [2024-02-13T19:01:05.792+0000] {dagbag.py:538} INFO - Filling up the DagBag from /opt/airflow/dags/star_wars_data_pipeline.py
[2024-02-13T19:01:05.855+0000] {logging_mixin.py:188} INFO - [2024-02-13T19:01:05.847+0000] {dagbag.py:348} ERROR - Failed to import: /opt/airflow/dags/star_wars_data_pipeline.py
Traceback (most recent call last):
  File "/home/airflow/.local/lib/python3.8/site-packages/airflow/models/dagbag.py", line 344, in parse
    loader.exec_module(new_module)
  File "<frozen importlib._bootstrap_external>", line 843, in exec_module
  File "<frozen importlib._bootstrap>", line 219, in _call_with_frames_removed
  File "/opt/airflow/dags/star_wars_data_pipeline.py", line 14, in <module>
    from script_results import generate_results_json as generate_results_json
ModuleNotFoundError: No module named 'script_results'
[2024-02-13T19:01:05.858+0000] {processor.py:842} WARNING - No viable dags retrieved from /opt/airflow/dags/star_wars_data_pipeline.py
[2024-02-13T19:01:05.897+0000] {processor.py:183} INFO - Processing /opt/airflow/dags/star_wars_data_pipeline.py took 0.114 seconds
[2024-02-13T19:01:10.999+0000] {processor.py:161} INFO - Started process (PID=290) to work on /opt/airflow/dags/star_wars_data_pipeline.py
[2024-02-13T19:01:11.001+0000] {processor.py:830} INFO - Processing file /opt/airflow/dags/star_wars_data_pipeline.py for tasks to queue
[2024-02-13T19:01:11.003+0000] {logging_mixin.py:188} INFO - [2024-02-13T19:01:11.003+0000] {dagbag.py:538} INFO - Filling up the DagBag from /opt/airflow/dags/star_wars_data_pipeline.py
[2024-02-13T19:01:11.058+0000] {logging_mixin.py:188} INFO - [2024-02-13T19:01:11.053+0000] {dagbag.py:348} ERROR - Failed to import: /opt/airflow/dags/star_wars_data_pipeline.py
Traceback (most recent call last):
  File "/home/airflow/.local/lib/python3.8/site-packages/airflow/models/dagbag.py", line 344, in parse
    loader.exec_module(new_module)
  File "<frozen importlib._bootstrap_external>", line 843, in exec_module
  File "<frozen importlib._bootstrap>", line 219, in _call_with_frames_removed
  File "/opt/airflow/dags/star_wars_data_pipeline.py", line 14, in <module>
    from script_results import generate_results_json as generate_results_json
ModuleNotFoundError: No module named 'script_results'
[2024-02-13T19:01:11.062+0000] {processor.py:842} WARNING - No viable dags retrieved from /opt/airflow/dags/star_wars_data_pipeline.py
[2024-02-13T19:01:11.092+0000] {processor.py:183} INFO - Processing /opt/airflow/dags/star_wars_data_pipeline.py took 0.096 seconds
[2024-02-13T19:01:16.174+0000] {processor.py:161} INFO - Started process (PID=291) to work on /opt/airflow/dags/star_wars_data_pipeline.py
[2024-02-13T19:01:16.176+0000] {processor.py:830} INFO - Processing file /opt/airflow/dags/star_wars_data_pipeline.py for tasks to queue
[2024-02-13T19:01:16.178+0000] {logging_mixin.py:188} INFO - [2024-02-13T19:01:16.178+0000] {dagbag.py:538} INFO - Filling up the DagBag from /opt/airflow/dags/star_wars_data_pipeline.py
[2024-02-13T19:01:16.227+0000] {logging_mixin.py:188} INFO - [2024-02-13T19:01:16.222+0000] {dagbag.py:348} ERROR - Failed to import: /opt/airflow/dags/star_wars_data_pipeline.py
Traceback (most recent call last):
  File "/home/airflow/.local/lib/python3.8/site-packages/airflow/models/dagbag.py", line 344, in parse
    loader.exec_module(new_module)
  File "<frozen importlib._bootstrap_external>", line 843, in exec_module
  File "<frozen importlib._bootstrap>", line 219, in _call_with_frames_removed
  File "/opt/airflow/dags/star_wars_data_pipeline.py", line 14, in <module>
    from script_results import generate_results_json as generate_results_json
ModuleNotFoundError: No module named 'script_results'
[2024-02-13T19:01:16.230+0000] {processor.py:842} WARNING - No viable dags retrieved from /opt/airflow/dags/star_wars_data_pipeline.py
[2024-02-13T19:01:16.260+0000] {processor.py:183} INFO - Processing /opt/airflow/dags/star_wars_data_pipeline.py took 0.090 seconds
[2024-02-13T19:01:21.349+0000] {processor.py:161} INFO - Started process (PID=300) to work on /opt/airflow/dags/star_wars_data_pipeline.py
[2024-02-13T19:01:21.351+0000] {processor.py:830} INFO - Processing file /opt/airflow/dags/star_wars_data_pipeline.py for tasks to queue
[2024-02-13T19:01:21.353+0000] {logging_mixin.py:188} INFO - [2024-02-13T19:01:21.353+0000] {dagbag.py:538} INFO - Filling up the DagBag from /opt/airflow/dags/star_wars_data_pipeline.py
[2024-02-13T19:01:21.406+0000] {logging_mixin.py:188} INFO - [2024-02-13T19:01:21.400+0000] {dagbag.py:348} ERROR - Failed to import: /opt/airflow/dags/star_wars_data_pipeline.py
Traceback (most recent call last):
  File "/home/airflow/.local/lib/python3.8/site-packages/airflow/models/dagbag.py", line 344, in parse
    loader.exec_module(new_module)
  File "<frozen importlib._bootstrap_external>", line 843, in exec_module
  File "<frozen importlib._bootstrap>", line 219, in _call_with_frames_removed
  File "/opt/airflow/dags/star_wars_data_pipeline.py", line 14, in <module>
    from script_results import generate_results_json as generate_results_json
ModuleNotFoundError: No module named 'script_results'
[2024-02-13T19:01:21.409+0000] {processor.py:842} WARNING - No viable dags retrieved from /opt/airflow/dags/star_wars_data_pipeline.py
[2024-02-13T19:01:21.438+0000] {processor.py:183} INFO - Processing /opt/airflow/dags/star_wars_data_pipeline.py took 0.092 seconds
[2024-02-13T19:01:26.492+0000] {processor.py:161} INFO - Started process (PID=301) to work on /opt/airflow/dags/star_wars_data_pipeline.py
[2024-02-13T19:01:26.493+0000] {processor.py:830} INFO - Processing file /opt/airflow/dags/star_wars_data_pipeline.py for tasks to queue
[2024-02-13T19:01:26.497+0000] {logging_mixin.py:188} INFO - [2024-02-13T19:01:26.496+0000] {dagbag.py:538} INFO - Filling up the DagBag from /opt/airflow/dags/star_wars_data_pipeline.py
[2024-02-13T19:01:26.554+0000] {logging_mixin.py:188} INFO - [2024-02-13T19:01:26.547+0000] {dagbag.py:348} ERROR - Failed to import: /opt/airflow/dags/star_wars_data_pipeline.py
Traceback (most recent call last):
  File "/home/airflow/.local/lib/python3.8/site-packages/airflow/models/dagbag.py", line 344, in parse
    loader.exec_module(new_module)
  File "<frozen importlib._bootstrap_external>", line 843, in exec_module
  File "<frozen importlib._bootstrap>", line 219, in _call_with_frames_removed
  File "/opt/airflow/dags/star_wars_data_pipeline.py", line 14, in <module>
    from script_results import generate_results_json as generate_results_json
ModuleNotFoundError: No module named 'script_results'
[2024-02-13T19:01:26.557+0000] {processor.py:842} WARNING - No viable dags retrieved from /opt/airflow/dags/star_wars_data_pipeline.py
[2024-02-13T19:01:26.591+0000] {processor.py:183} INFO - Processing /opt/airflow/dags/star_wars_data_pipeline.py took 0.102 seconds
[2024-02-13T19:01:31.703+0000] {processor.py:161} INFO - Started process (PID=302) to work on /opt/airflow/dags/star_wars_data_pipeline.py
[2024-02-13T19:01:31.706+0000] {processor.py:830} INFO - Processing file /opt/airflow/dags/star_wars_data_pipeline.py for tasks to queue
[2024-02-13T19:01:31.709+0000] {logging_mixin.py:188} INFO - [2024-02-13T19:01:31.709+0000] {dagbag.py:538} INFO - Filling up the DagBag from /opt/airflow/dags/star_wars_data_pipeline.py
[2024-02-13T19:01:31.793+0000] {logging_mixin.py:188} INFO - [2024-02-13T19:01:31.781+0000] {dagbag.py:348} ERROR - Failed to import: /opt/airflow/dags/star_wars_data_pipeline.py
Traceback (most recent call last):
  File "/home/airflow/.local/lib/python3.8/site-packages/airflow/models/dagbag.py", line 344, in parse
    loader.exec_module(new_module)
  File "<frozen importlib._bootstrap_external>", line 843, in exec_module
  File "<frozen importlib._bootstrap>", line 219, in _call_with_frames_removed
  File "/opt/airflow/dags/star_wars_data_pipeline.py", line 14, in <module>
    from script_results import generate_results_json as generate_results_json
ModuleNotFoundError: No module named 'script_results'
[2024-02-13T19:01:31.797+0000] {processor.py:842} WARNING - No viable dags retrieved from /opt/airflow/dags/star_wars_data_pipeline.py
[2024-02-13T19:01:31.841+0000] {processor.py:183} INFO - Processing /opt/airflow/dags/star_wars_data_pipeline.py took 0.146 seconds
[2024-02-13T19:01:36.962+0000] {processor.py:161} INFO - Started process (PID=311) to work on /opt/airflow/dags/star_wars_data_pipeline.py
[2024-02-13T19:01:36.964+0000] {processor.py:830} INFO - Processing file /opt/airflow/dags/star_wars_data_pipeline.py for tasks to queue
[2024-02-13T19:01:36.967+0000] {logging_mixin.py:188} INFO - [2024-02-13T19:01:36.966+0000] {dagbag.py:538} INFO - Filling up the DagBag from /opt/airflow/dags/star_wars_data_pipeline.py
[2024-02-13T19:01:37.021+0000] {logging_mixin.py:188} INFO - [2024-02-13T19:01:37.015+0000] {dagbag.py:348} ERROR - Failed to import: /opt/airflow/dags/star_wars_data_pipeline.py
Traceback (most recent call last):
  File "/home/airflow/.local/lib/python3.8/site-packages/airflow/models/dagbag.py", line 344, in parse
    loader.exec_module(new_module)
  File "<frozen importlib._bootstrap_external>", line 843, in exec_module
  File "<frozen importlib._bootstrap>", line 219, in _call_with_frames_removed
  File "/opt/airflow/dags/star_wars_data_pipeline.py", line 14, in <module>
    from script_results import generate_results_json as generate_results_json
ModuleNotFoundError: No module named 'script_results'
[2024-02-13T19:01:37.024+0000] {processor.py:842} WARNING - No viable dags retrieved from /opt/airflow/dags/star_wars_data_pipeline.py
[2024-02-13T19:01:37.055+0000] {processor.py:183} INFO - Processing /opt/airflow/dags/star_wars_data_pipeline.py took 0.098 seconds
[2024-02-13T19:01:42.139+0000] {processor.py:161} INFO - Started process (PID=312) to work on /opt/airflow/dags/star_wars_data_pipeline.py
[2024-02-13T19:01:42.141+0000] {processor.py:830} INFO - Processing file /opt/airflow/dags/star_wars_data_pipeline.py for tasks to queue
[2024-02-13T19:01:42.143+0000] {logging_mixin.py:188} INFO - [2024-02-13T19:01:42.143+0000] {dagbag.py:538} INFO - Filling up the DagBag from /opt/airflow/dags/star_wars_data_pipeline.py
[2024-02-13T19:01:42.193+0000] {logging_mixin.py:188} INFO - [2024-02-13T19:01:42.188+0000] {dagbag.py:348} ERROR - Failed to import: /opt/airflow/dags/star_wars_data_pipeline.py
Traceback (most recent call last):
  File "/home/airflow/.local/lib/python3.8/site-packages/airflow/models/dagbag.py", line 344, in parse
    loader.exec_module(new_module)
  File "<frozen importlib._bootstrap_external>", line 843, in exec_module
  File "<frozen importlib._bootstrap>", line 219, in _call_with_frames_removed
  File "/opt/airflow/dags/star_wars_data_pipeline.py", line 14, in <module>
    from script_results import generate_results_json as generate_results_json
ModuleNotFoundError: No module named 'script_results'
[2024-02-13T19:01:42.196+0000] {processor.py:842} WARNING - No viable dags retrieved from /opt/airflow/dags/star_wars_data_pipeline.py
[2024-02-13T19:01:42.224+0000] {processor.py:183} INFO - Processing /opt/airflow/dags/star_wars_data_pipeline.py took 0.088 seconds
[2024-02-13T19:01:47.298+0000] {processor.py:161} INFO - Started process (PID=313) to work on /opt/airflow/dags/star_wars_data_pipeline.py
[2024-02-13T19:01:47.299+0000] {processor.py:830} INFO - Processing file /opt/airflow/dags/star_wars_data_pipeline.py for tasks to queue
[2024-02-13T19:01:47.302+0000] {logging_mixin.py:188} INFO - [2024-02-13T19:01:47.301+0000] {dagbag.py:538} INFO - Filling up the DagBag from /opt/airflow/dags/star_wars_data_pipeline.py
[2024-02-13T19:01:47.343+0000] {logging_mixin.py:188} INFO - [2024-02-13T19:01:47.338+0000] {dagbag.py:348} ERROR - Failed to import: /opt/airflow/dags/star_wars_data_pipeline.py
Traceback (most recent call last):
  File "/home/airflow/.local/lib/python3.8/site-packages/airflow/models/dagbag.py", line 344, in parse
    loader.exec_module(new_module)
  File "<frozen importlib._bootstrap_external>", line 843, in exec_module
  File "<frozen importlib._bootstrap>", line 219, in _call_with_frames_removed
  File "/opt/airflow/dags/star_wars_data_pipeline.py", line 14, in <module>
    from script_results import generate_results_json as generate_results_json
ModuleNotFoundError: No module named 'script_results'
[2024-02-13T19:01:47.345+0000] {processor.py:842} WARNING - No viable dags retrieved from /opt/airflow/dags/star_wars_data_pipeline.py
[2024-02-13T19:01:47.372+0000] {processor.py:183} INFO - Processing /opt/airflow/dags/star_wars_data_pipeline.py took 0.078 seconds
[2024-02-13T19:01:52.462+0000] {processor.py:161} INFO - Started process (PID=322) to work on /opt/airflow/dags/star_wars_data_pipeline.py
[2024-02-13T19:01:52.464+0000] {processor.py:830} INFO - Processing file /opt/airflow/dags/star_wars_data_pipeline.py for tasks to queue
[2024-02-13T19:01:52.467+0000] {logging_mixin.py:188} INFO - [2024-02-13T19:01:52.467+0000] {dagbag.py:538} INFO - Filling up the DagBag from /opt/airflow/dags/star_wars_data_pipeline.py
[2024-02-13T19:01:52.528+0000] {logging_mixin.py:188} INFO - [2024-02-13T19:01:52.523+0000] {dagbag.py:348} ERROR - Failed to import: /opt/airflow/dags/star_wars_data_pipeline.py
Traceback (most recent call last):
  File "/home/airflow/.local/lib/python3.8/site-packages/airflow/models/dagbag.py", line 344, in parse
    loader.exec_module(new_module)
  File "<frozen importlib._bootstrap_external>", line 843, in exec_module
  File "<frozen importlib._bootstrap>", line 219, in _call_with_frames_removed
  File "/opt/airflow/dags/star_wars_data_pipeline.py", line 14, in <module>
    from script_results import generate_results_json as generate_results_json
ModuleNotFoundError: No module named 'script_results'
[2024-02-13T19:01:52.531+0000] {processor.py:842} WARNING - No viable dags retrieved from /opt/airflow/dags/star_wars_data_pipeline.py
[2024-02-13T19:01:52.567+0000] {processor.py:183} INFO - Processing /opt/airflow/dags/star_wars_data_pipeline.py took 0.108 seconds
[2024-02-13T19:01:57.668+0000] {processor.py:161} INFO - Started process (PID=323) to work on /opt/airflow/dags/star_wars_data_pipeline.py
[2024-02-13T19:01:57.670+0000] {processor.py:830} INFO - Processing file /opt/airflow/dags/star_wars_data_pipeline.py for tasks to queue
[2024-02-13T19:01:57.674+0000] {logging_mixin.py:188} INFO - [2024-02-13T19:01:57.674+0000] {dagbag.py:538} INFO - Filling up the DagBag from /opt/airflow/dags/star_wars_data_pipeline.py
[2024-02-13T19:01:57.738+0000] {logging_mixin.py:188} INFO - [2024-02-13T19:01:57.730+0000] {dagbag.py:348} ERROR - Failed to import: /opt/airflow/dags/star_wars_data_pipeline.py
Traceback (most recent call last):
  File "/home/airflow/.local/lib/python3.8/site-packages/airflow/models/dagbag.py", line 344, in parse
    loader.exec_module(new_module)
  File "<frozen importlib._bootstrap_external>", line 843, in exec_module
  File "<frozen importlib._bootstrap>", line 219, in _call_with_frames_removed
  File "/opt/airflow/dags/star_wars_data_pipeline.py", line 14, in <module>
    from script_results import generate_results_json as generate_results_json
ModuleNotFoundError: No module named 'script_results'
[2024-02-13T19:01:57.742+0000] {processor.py:842} WARNING - No viable dags retrieved from /opt/airflow/dags/star_wars_data_pipeline.py
[2024-02-13T19:01:57.773+0000] {processor.py:183} INFO - Processing /opt/airflow/dags/star_wars_data_pipeline.py took 0.109 seconds
[2024-02-13T19:02:02.865+0000] {processor.py:161} INFO - Started process (PID=331) to work on /opt/airflow/dags/star_wars_data_pipeline.py
[2024-02-13T19:02:02.867+0000] {processor.py:830} INFO - Processing file /opt/airflow/dags/star_wars_data_pipeline.py for tasks to queue
[2024-02-13T19:02:02.871+0000] {logging_mixin.py:188} INFO - [2024-02-13T19:02:02.870+0000] {dagbag.py:538} INFO - Filling up the DagBag from /opt/airflow/dags/star_wars_data_pipeline.py
[2024-02-13T19:02:02.920+0000] {logging_mixin.py:188} INFO - [2024-02-13T19:02:02.915+0000] {dagbag.py:348} ERROR - Failed to import: /opt/airflow/dags/star_wars_data_pipeline.py
Traceback (most recent call last):
  File "/home/airflow/.local/lib/python3.8/site-packages/airflow/models/dagbag.py", line 344, in parse
    loader.exec_module(new_module)
  File "<frozen importlib._bootstrap_external>", line 843, in exec_module
  File "<frozen importlib._bootstrap>", line 219, in _call_with_frames_removed
  File "/opt/airflow/dags/star_wars_data_pipeline.py", line 14, in <module>
    from script_results import generate_results_json as generate_results_json
ModuleNotFoundError: No module named 'script_results'
[2024-02-13T19:02:02.922+0000] {processor.py:842} WARNING - No viable dags retrieved from /opt/airflow/dags/star_wars_data_pipeline.py
[2024-02-13T19:02:02.954+0000] {processor.py:183} INFO - Processing /opt/airflow/dags/star_wars_data_pipeline.py took 0.092 seconds
[2024-02-13T19:02:08.074+0000] {processor.py:161} INFO - Started process (PID=333) to work on /opt/airflow/dags/star_wars_data_pipeline.py
[2024-02-13T19:02:08.077+0000] {processor.py:830} INFO - Processing file /opt/airflow/dags/star_wars_data_pipeline.py for tasks to queue
[2024-02-13T19:02:08.083+0000] {logging_mixin.py:188} INFO - [2024-02-13T19:02:08.082+0000] {dagbag.py:538} INFO - Filling up the DagBag from /opt/airflow/dags/star_wars_data_pipeline.py
[2024-02-13T19:02:08.147+0000] {logging_mixin.py:188} INFO - [2024-02-13T19:02:08.139+0000] {dagbag.py:348} ERROR - Failed to import: /opt/airflow/dags/star_wars_data_pipeline.py
Traceback (most recent call last):
  File "/home/airflow/.local/lib/python3.8/site-packages/airflow/models/dagbag.py", line 344, in parse
    loader.exec_module(new_module)
  File "<frozen importlib._bootstrap_external>", line 843, in exec_module
  File "<frozen importlib._bootstrap>", line 219, in _call_with_frames_removed
  File "/opt/airflow/dags/star_wars_data_pipeline.py", line 14, in <module>
    from script_results import generate_results_json as generate_results_json
ModuleNotFoundError: No module named 'script_results'
[2024-02-13T19:02:08.150+0000] {processor.py:842} WARNING - No viable dags retrieved from /opt/airflow/dags/star_wars_data_pipeline.py
[2024-02-13T19:02:08.181+0000] {processor.py:183} INFO - Processing /opt/airflow/dags/star_wars_data_pipeline.py took 0.114 seconds
[2024-02-13T19:02:13.264+0000] {processor.py:161} INFO - Started process (PID=334) to work on /opt/airflow/dags/star_wars_data_pipeline.py
[2024-02-13T19:02:13.266+0000] {processor.py:830} INFO - Processing file /opt/airflow/dags/star_wars_data_pipeline.py for tasks to queue
[2024-02-13T19:02:13.269+0000] {logging_mixin.py:188} INFO - [2024-02-13T19:02:13.268+0000] {dagbag.py:538} INFO - Filling up the DagBag from /opt/airflow/dags/star_wars_data_pipeline.py
[2024-02-13T19:02:13.314+0000] {logging_mixin.py:188} INFO - [2024-02-13T19:02:13.310+0000] {dagbag.py:348} ERROR - Failed to import: /opt/airflow/dags/star_wars_data_pipeline.py
Traceback (most recent call last):
  File "/home/airflow/.local/lib/python3.8/site-packages/airflow/models/dagbag.py", line 344, in parse
    loader.exec_module(new_module)
  File "<frozen importlib._bootstrap_external>", line 843, in exec_module
  File "<frozen importlib._bootstrap>", line 219, in _call_with_frames_removed
  File "/opt/airflow/dags/star_wars_data_pipeline.py", line 14, in <module>
    from script_results import generate_results_json as generate_results_json
ModuleNotFoundError: No module named 'script_results'
[2024-02-13T19:02:13.317+0000] {processor.py:842} WARNING - No viable dags retrieved from /opt/airflow/dags/star_wars_data_pipeline.py
[2024-02-13T19:02:13.348+0000] {processor.py:183} INFO - Processing /opt/airflow/dags/star_wars_data_pipeline.py took 0.086 seconds
[2024-02-13T19:02:18.432+0000] {processor.py:161} INFO - Started process (PID=343) to work on /opt/airflow/dags/star_wars_data_pipeline.py
[2024-02-13T19:02:18.433+0000] {processor.py:830} INFO - Processing file /opt/airflow/dags/star_wars_data_pipeline.py for tasks to queue
[2024-02-13T19:02:18.436+0000] {logging_mixin.py:188} INFO - [2024-02-13T19:02:18.435+0000] {dagbag.py:538} INFO - Filling up the DagBag from /opt/airflow/dags/star_wars_data_pipeline.py
[2024-02-13T19:02:18.486+0000] {logging_mixin.py:188} INFO - [2024-02-13T19:02:18.481+0000] {dagbag.py:348} ERROR - Failed to import: /opt/airflow/dags/star_wars_data_pipeline.py
Traceback (most recent call last):
  File "/home/airflow/.local/lib/python3.8/site-packages/airflow/models/dagbag.py", line 344, in parse
    loader.exec_module(new_module)
  File "<frozen importlib._bootstrap_external>", line 843, in exec_module
  File "<frozen importlib._bootstrap>", line 219, in _call_with_frames_removed
  File "/opt/airflow/dags/star_wars_data_pipeline.py", line 14, in <module>
    from script_results import generate_results_json as generate_results_json
ModuleNotFoundError: No module named 'script_results'
[2024-02-13T19:02:18.489+0000] {processor.py:842} WARNING - No viable dags retrieved from /opt/airflow/dags/star_wars_data_pipeline.py
[2024-02-13T19:02:18.527+0000] {processor.py:183} INFO - Processing /opt/airflow/dags/star_wars_data_pipeline.py took 0.098 seconds
[2024-02-13T19:02:23.617+0000] {processor.py:161} INFO - Started process (PID=344) to work on /opt/airflow/dags/star_wars_data_pipeline.py
[2024-02-13T19:02:23.620+0000] {processor.py:830} INFO - Processing file /opt/airflow/dags/star_wars_data_pipeline.py for tasks to queue
[2024-02-13T19:02:23.622+0000] {logging_mixin.py:188} INFO - [2024-02-13T19:02:23.621+0000] {dagbag.py:538} INFO - Filling up the DagBag from /opt/airflow/dags/star_wars_data_pipeline.py
[2024-02-13T19:02:23.675+0000] {logging_mixin.py:188} INFO - [2024-02-13T19:02:23.670+0000] {dagbag.py:348} ERROR - Failed to import: /opt/airflow/dags/star_wars_data_pipeline.py
Traceback (most recent call last):
  File "/home/airflow/.local/lib/python3.8/site-packages/airflow/models/dagbag.py", line 344, in parse
    loader.exec_module(new_module)
  File "<frozen importlib._bootstrap_external>", line 843, in exec_module
  File "<frozen importlib._bootstrap>", line 219, in _call_with_frames_removed
  File "/opt/airflow/dags/star_wars_data_pipeline.py", line 14, in <module>
    from script_results import generate_results_json as generate_results_json
ModuleNotFoundError: No module named 'script_results'
[2024-02-13T19:02:23.678+0000] {processor.py:842} WARNING - No viable dags retrieved from /opt/airflow/dags/star_wars_data_pipeline.py
[2024-02-13T19:02:23.711+0000] {processor.py:183} INFO - Processing /opt/airflow/dags/star_wars_data_pipeline.py took 0.096 seconds
[2024-02-13T19:02:28.820+0000] {processor.py:161} INFO - Started process (PID=345) to work on /opt/airflow/dags/star_wars_data_pipeline.py
[2024-02-13T19:02:28.822+0000] {processor.py:830} INFO - Processing file /opt/airflow/dags/star_wars_data_pipeline.py for tasks to queue
[2024-02-13T19:02:28.826+0000] {logging_mixin.py:188} INFO - [2024-02-13T19:02:28.825+0000] {dagbag.py:538} INFO - Filling up the DagBag from /opt/airflow/dags/star_wars_data_pipeline.py
[2024-02-13T19:02:28.903+0000] {logging_mixin.py:188} INFO - [2024-02-13T19:02:28.896+0000] {dagbag.py:348} ERROR - Failed to import: /opt/airflow/dags/star_wars_data_pipeline.py
Traceback (most recent call last):
  File "/home/airflow/.local/lib/python3.8/site-packages/airflow/models/dagbag.py", line 344, in parse
    loader.exec_module(new_module)
  File "<frozen importlib._bootstrap_external>", line 843, in exec_module
  File "<frozen importlib._bootstrap>", line 219, in _call_with_frames_removed
  File "/opt/airflow/dags/star_wars_data_pipeline.py", line 14, in <module>
    from script_results import generate_results_json as generate_results_json
ModuleNotFoundError: No module named 'script_results'
[2024-02-13T19:02:28.906+0000] {processor.py:842} WARNING - No viable dags retrieved from /opt/airflow/dags/star_wars_data_pipeline.py
[2024-02-13T19:02:28.949+0000] {processor.py:183} INFO - Processing /opt/airflow/dags/star_wars_data_pipeline.py took 0.133 seconds
[2024-02-13T19:02:34.071+0000] {processor.py:161} INFO - Started process (PID=354) to work on /opt/airflow/dags/star_wars_data_pipeline.py
[2024-02-13T19:02:34.074+0000] {processor.py:830} INFO - Processing file /opt/airflow/dags/star_wars_data_pipeline.py for tasks to queue
[2024-02-13T19:02:34.080+0000] {logging_mixin.py:188} INFO - [2024-02-13T19:02:34.078+0000] {dagbag.py:538} INFO - Filling up the DagBag from /opt/airflow/dags/star_wars_data_pipeline.py
[2024-02-13T19:02:34.167+0000] {logging_mixin.py:188} INFO - [2024-02-13T19:02:34.157+0000] {dagbag.py:348} ERROR - Failed to import: /opt/airflow/dags/star_wars_data_pipeline.py
Traceback (most recent call last):
  File "/home/airflow/.local/lib/python3.8/site-packages/airflow/models/dagbag.py", line 344, in parse
    loader.exec_module(new_module)
  File "<frozen importlib._bootstrap_external>", line 843, in exec_module
  File "<frozen importlib._bootstrap>", line 219, in _call_with_frames_removed
  File "/opt/airflow/dags/star_wars_data_pipeline.py", line 14, in <module>
    from script_results import generate_results_json as generate_results_json
ModuleNotFoundError: No module named 'script_results'
[2024-02-13T19:02:34.171+0000] {processor.py:842} WARNING - No viable dags retrieved from /opt/airflow/dags/star_wars_data_pipeline.py
[2024-02-13T19:02:34.213+0000] {processor.py:183} INFO - Processing /opt/airflow/dags/star_wars_data_pipeline.py took 0.149 seconds
[2024-02-13T19:02:39.326+0000] {processor.py:161} INFO - Started process (PID=355) to work on /opt/airflow/dags/star_wars_data_pipeline.py
[2024-02-13T19:02:39.329+0000] {processor.py:830} INFO - Processing file /opt/airflow/dags/star_wars_data_pipeline.py for tasks to queue
[2024-02-13T19:02:39.332+0000] {logging_mixin.py:188} INFO - [2024-02-13T19:02:39.331+0000] {dagbag.py:538} INFO - Filling up the DagBag from /opt/airflow/dags/star_wars_data_pipeline.py
[2024-02-13T19:02:39.392+0000] {logging_mixin.py:188} INFO - [2024-02-13T19:02:39.387+0000] {dagbag.py:348} ERROR - Failed to import: /opt/airflow/dags/star_wars_data_pipeline.py
Traceback (most recent call last):
  File "/home/airflow/.local/lib/python3.8/site-packages/airflow/models/dagbag.py", line 344, in parse
    loader.exec_module(new_module)
  File "<frozen importlib._bootstrap_external>", line 843, in exec_module
  File "<frozen importlib._bootstrap>", line 219, in _call_with_frames_removed
  File "/opt/airflow/dags/star_wars_data_pipeline.py", line 14, in <module>
    from script_results import generate_results_json as generate_results_json
ModuleNotFoundError: No module named 'script_results'
[2024-02-13T19:02:39.396+0000] {processor.py:842} WARNING - No viable dags retrieved from /opt/airflow/dags/star_wars_data_pipeline.py
[2024-02-13T19:02:39.440+0000] {processor.py:183} INFO - Processing /opt/airflow/dags/star_wars_data_pipeline.py took 0.117 seconds
[2024-02-13T19:02:44.521+0000] {processor.py:161} INFO - Started process (PID=356) to work on /opt/airflow/dags/star_wars_data_pipeline.py
[2024-02-13T19:02:44.524+0000] {processor.py:830} INFO - Processing file /opt/airflow/dags/star_wars_data_pipeline.py for tasks to queue
[2024-02-13T19:02:44.527+0000] {logging_mixin.py:188} INFO - [2024-02-13T19:02:44.527+0000] {dagbag.py:538} INFO - Filling up the DagBag from /opt/airflow/dags/star_wars_data_pipeline.py
[2024-02-13T19:02:44.568+0000] {logging_mixin.py:188} INFO - [2024-02-13T19:02:44.564+0000] {dagbag.py:348} ERROR - Failed to import: /opt/airflow/dags/star_wars_data_pipeline.py
Traceback (most recent call last):
  File "/home/airflow/.local/lib/python3.8/site-packages/airflow/models/dagbag.py", line 344, in parse
    loader.exec_module(new_module)
  File "<frozen importlib._bootstrap_external>", line 843, in exec_module
  File "<frozen importlib._bootstrap>", line 219, in _call_with_frames_removed
  File "/opt/airflow/dags/star_wars_data_pipeline.py", line 14, in <module>
    from script_results import generate_results_json as generate_results_json
ModuleNotFoundError: No module named 'script_results'
[2024-02-13T19:02:44.571+0000] {processor.py:842} WARNING - No viable dags retrieved from /opt/airflow/dags/star_wars_data_pipeline.py
[2024-02-13T19:02:44.599+0000] {processor.py:183} INFO - Processing /opt/airflow/dags/star_wars_data_pipeline.py took 0.081 seconds
[2024-02-13T19:02:49.821+0000] {processor.py:161} INFO - Started process (PID=365) to work on /opt/airflow/dags/star_wars_data_pipeline.py
[2024-02-13T19:02:49.822+0000] {processor.py:830} INFO - Processing file /opt/airflow/dags/star_wars_data_pipeline.py for tasks to queue
[2024-02-13T19:02:49.825+0000] {logging_mixin.py:188} INFO - [2024-02-13T19:02:49.824+0000] {dagbag.py:538} INFO - Filling up the DagBag from /opt/airflow/dags/star_wars_data_pipeline.py
[2024-02-13T19:02:49.872+0000] {logging_mixin.py:188} INFO - [2024-02-13T19:02:49.867+0000] {dagbag.py:348} ERROR - Failed to import: /opt/airflow/dags/star_wars_data_pipeline.py
Traceback (most recent call last):
  File "/home/airflow/.local/lib/python3.8/site-packages/airflow/models/dagbag.py", line 344, in parse
    loader.exec_module(new_module)
  File "<frozen importlib._bootstrap_external>", line 843, in exec_module
  File "<frozen importlib._bootstrap>", line 219, in _call_with_frames_removed
  File "/opt/airflow/dags/star_wars_data_pipeline.py", line 14, in <module>
    from script_results import generate_results_json as generate_results_json
ModuleNotFoundError: No module named 'script_results'
[2024-02-13T19:02:49.873+0000] {processor.py:842} WARNING - No viable dags retrieved from /opt/airflow/dags/star_wars_data_pipeline.py
[2024-02-13T19:02:49.904+0000] {processor.py:183} INFO - Processing /opt/airflow/dags/star_wars_data_pipeline.py took 0.086 seconds
[2024-02-13T19:02:54.985+0000] {processor.py:161} INFO - Started process (PID=366) to work on /opt/airflow/dags/star_wars_data_pipeline.py
[2024-02-13T19:02:54.986+0000] {processor.py:830} INFO - Processing file /opt/airflow/dags/star_wars_data_pipeline.py for tasks to queue
[2024-02-13T19:02:54.988+0000] {logging_mixin.py:188} INFO - [2024-02-13T19:02:54.988+0000] {dagbag.py:538} INFO - Filling up the DagBag from /opt/airflow/dags/star_wars_data_pipeline.py
[2024-02-13T19:02:55.031+0000] {logging_mixin.py:188} INFO - [2024-02-13T19:02:55.026+0000] {dagbag.py:348} ERROR - Failed to import: /opt/airflow/dags/star_wars_data_pipeline.py
Traceback (most recent call last):
  File "/home/airflow/.local/lib/python3.8/site-packages/airflow/models/dagbag.py", line 344, in parse
    loader.exec_module(new_module)
  File "<frozen importlib._bootstrap_external>", line 843, in exec_module
  File "<frozen importlib._bootstrap>", line 219, in _call_with_frames_removed
  File "/opt/airflow/dags/star_wars_data_pipeline.py", line 14, in <module>
    from script_results import generate_results_json as generate_results_json
ModuleNotFoundError: No module named 'script_results'
[2024-02-13T19:02:55.033+0000] {processor.py:842} WARNING - No viable dags retrieved from /opt/airflow/dags/star_wars_data_pipeline.py
[2024-02-13T19:02:55.060+0000] {processor.py:183} INFO - Processing /opt/airflow/dags/star_wars_data_pipeline.py took 0.078 seconds
[2024-02-13T19:03:00.166+0000] {processor.py:161} INFO - Started process (PID=375) to work on /opt/airflow/dags/star_wars_data_pipeline.py
[2024-02-13T19:03:00.167+0000] {processor.py:830} INFO - Processing file /opt/airflow/dags/star_wars_data_pipeline.py for tasks to queue
[2024-02-13T19:03:00.170+0000] {logging_mixin.py:188} INFO - [2024-02-13T19:03:00.169+0000] {dagbag.py:538} INFO - Filling up the DagBag from /opt/airflow/dags/star_wars_data_pipeline.py
[2024-02-13T19:03:00.235+0000] {logging_mixin.py:188} INFO - [2024-02-13T19:03:00.229+0000] {dagbag.py:348} ERROR - Failed to import: /opt/airflow/dags/star_wars_data_pipeline.py
Traceback (most recent call last):
  File "/home/airflow/.local/lib/python3.8/site-packages/airflow/models/dagbag.py", line 344, in parse
    loader.exec_module(new_module)
  File "<frozen importlib._bootstrap_external>", line 843, in exec_module
  File "<frozen importlib._bootstrap>", line 219, in _call_with_frames_removed
  File "/opt/airflow/dags/star_wars_data_pipeline.py", line 14, in <module>
    from script_results import generate_results_json as generate_results_json
ModuleNotFoundError: No module named 'script_results'
[2024-02-13T19:03:00.240+0000] {processor.py:842} WARNING - No viable dags retrieved from /opt/airflow/dags/star_wars_data_pipeline.py
[2024-02-13T19:03:00.283+0000] {processor.py:183} INFO - Processing /opt/airflow/dags/star_wars_data_pipeline.py took 0.121 seconds
[2024-02-13T19:03:05.376+0000] {processor.py:161} INFO - Started process (PID=376) to work on /opt/airflow/dags/star_wars_data_pipeline.py
[2024-02-13T19:03:05.378+0000] {processor.py:830} INFO - Processing file /opt/airflow/dags/star_wars_data_pipeline.py for tasks to queue
[2024-02-13T19:03:05.381+0000] {logging_mixin.py:188} INFO - [2024-02-13T19:03:05.380+0000] {dagbag.py:538} INFO - Filling up the DagBag from /opt/airflow/dags/star_wars_data_pipeline.py
[2024-02-13T19:03:05.426+0000] {logging_mixin.py:188} INFO - [2024-02-13T19:03:05.420+0000] {dagbag.py:348} ERROR - Failed to import: /opt/airflow/dags/star_wars_data_pipeline.py
Traceback (most recent call last):
  File "/home/airflow/.local/lib/python3.8/site-packages/airflow/models/dagbag.py", line 344, in parse
    loader.exec_module(new_module)
  File "<frozen importlib._bootstrap_external>", line 843, in exec_module
  File "<frozen importlib._bootstrap>", line 219, in _call_with_frames_removed
  File "/opt/airflow/dags/star_wars_data_pipeline.py", line 14, in <module>
    from script_results import generate_results_json as generate_results_json
ModuleNotFoundError: No module named 'script_results'
[2024-02-13T19:03:05.428+0000] {processor.py:842} WARNING - No viable dags retrieved from /opt/airflow/dags/star_wars_data_pipeline.py
[2024-02-13T19:03:05.455+0000] {processor.py:183} INFO - Processing /opt/airflow/dags/star_wars_data_pipeline.py took 0.083 seconds
[2024-02-13T19:03:10.511+0000] {processor.py:161} INFO - Started process (PID=377) to work on /opt/airflow/dags/star_wars_data_pipeline.py
[2024-02-13T19:03:10.513+0000] {processor.py:830} INFO - Processing file /opt/airflow/dags/star_wars_data_pipeline.py for tasks to queue
[2024-02-13T19:03:10.515+0000] {logging_mixin.py:188} INFO - [2024-02-13T19:03:10.514+0000] {dagbag.py:538} INFO - Filling up the DagBag from /opt/airflow/dags/star_wars_data_pipeline.py
[2024-02-13T19:03:10.562+0000] {logging_mixin.py:188} INFO - [2024-02-13T19:03:10.556+0000] {dagbag.py:348} ERROR - Failed to import: /opt/airflow/dags/star_wars_data_pipeline.py
Traceback (most recent call last):
  File "/home/airflow/.local/lib/python3.8/site-packages/airflow/models/dagbag.py", line 344, in parse
    loader.exec_module(new_module)
  File "<frozen importlib._bootstrap_external>", line 843, in exec_module
  File "<frozen importlib._bootstrap>", line 219, in _call_with_frames_removed
  File "/opt/airflow/dags/star_wars_data_pipeline.py", line 14, in <module>
    from script_results import generate_results_json as generate_results_json
ModuleNotFoundError: No module named 'script_results'
[2024-02-13T19:03:10.564+0000] {processor.py:842} WARNING - No viable dags retrieved from /opt/airflow/dags/star_wars_data_pipeline.py
[2024-02-13T19:03:10.590+0000] {processor.py:183} INFO - Processing /opt/airflow/dags/star_wars_data_pipeline.py took 0.083 seconds
[2024-02-13T19:03:15.687+0000] {processor.py:161} INFO - Started process (PID=386) to work on /opt/airflow/dags/star_wars_data_pipeline.py
[2024-02-13T19:03:15.689+0000] {processor.py:830} INFO - Processing file /opt/airflow/dags/star_wars_data_pipeline.py for tasks to queue
[2024-02-13T19:03:15.693+0000] {logging_mixin.py:188} INFO - [2024-02-13T19:03:15.692+0000] {dagbag.py:538} INFO - Filling up the DagBag from /opt/airflow/dags/star_wars_data_pipeline.py
[2024-02-13T19:03:15.773+0000] {logging_mixin.py:188} INFO - [2024-02-13T19:03:15.765+0000] {dagbag.py:348} ERROR - Failed to import: /opt/airflow/dags/star_wars_data_pipeline.py
Traceback (most recent call last):
  File "/home/airflow/.local/lib/python3.8/site-packages/airflow/models/dagbag.py", line 344, in parse
    loader.exec_module(new_module)
  File "<frozen importlib._bootstrap_external>", line 843, in exec_module
  File "<frozen importlib._bootstrap>", line 219, in _call_with_frames_removed
  File "/opt/airflow/dags/star_wars_data_pipeline.py", line 14, in <module>
    from script_results import generate_results_json as generate_results_json
ModuleNotFoundError: No module named 'script_results'
[2024-02-13T19:03:15.776+0000] {processor.py:842} WARNING - No viable dags retrieved from /opt/airflow/dags/star_wars_data_pipeline.py
[2024-02-13T19:03:15.822+0000] {processor.py:183} INFO - Processing /opt/airflow/dags/star_wars_data_pipeline.py took 0.139 seconds
[2024-02-13T19:03:20.936+0000] {processor.py:161} INFO - Started process (PID=387) to work on /opt/airflow/dags/star_wars_data_pipeline.py
[2024-02-13T19:03:20.938+0000] {processor.py:830} INFO - Processing file /opt/airflow/dags/star_wars_data_pipeline.py for tasks to queue
[2024-02-13T19:03:20.941+0000] {logging_mixin.py:188} INFO - [2024-02-13T19:03:20.941+0000] {dagbag.py:538} INFO - Filling up the DagBag from /opt/airflow/dags/star_wars_data_pipeline.py
[2024-02-13T19:03:21.016+0000] {logging_mixin.py:188} INFO - [2024-02-13T19:03:21.007+0000] {dagbag.py:348} ERROR - Failed to import: /opt/airflow/dags/star_wars_data_pipeline.py
Traceback (most recent call last):
  File "/home/airflow/.local/lib/python3.8/site-packages/airflow/models/dagbag.py", line 344, in parse
    loader.exec_module(new_module)
  File "<frozen importlib._bootstrap_external>", line 843, in exec_module
  File "<frozen importlib._bootstrap>", line 219, in _call_with_frames_removed
  File "/opt/airflow/dags/star_wars_data_pipeline.py", line 14, in <module>
    from script_results import generate_results_json as generate_results_json
ModuleNotFoundError: No module named 'script_results'
[2024-02-13T19:03:21.019+0000] {processor.py:842} WARNING - No viable dags retrieved from /opt/airflow/dags/star_wars_data_pipeline.py
[2024-02-13T19:03:21.049+0000] {processor.py:183} INFO - Processing /opt/airflow/dags/star_wars_data_pipeline.py took 0.121 seconds
[2024-02-13T19:03:26.133+0000] {processor.py:161} INFO - Started process (PID=388) to work on /opt/airflow/dags/star_wars_data_pipeline.py
[2024-02-13T19:03:26.134+0000] {processor.py:830} INFO - Processing file /opt/airflow/dags/star_wars_data_pipeline.py for tasks to queue
[2024-02-13T19:03:26.137+0000] {logging_mixin.py:188} INFO - [2024-02-13T19:03:26.136+0000] {dagbag.py:538} INFO - Filling up the DagBag from /opt/airflow/dags/star_wars_data_pipeline.py
[2024-02-13T19:03:26.182+0000] {logging_mixin.py:188} INFO - [2024-02-13T19:03:26.177+0000] {dagbag.py:348} ERROR - Failed to import: /opt/airflow/dags/star_wars_data_pipeline.py
Traceback (most recent call last):
  File "/home/airflow/.local/lib/python3.8/site-packages/airflow/models/dagbag.py", line 344, in parse
    loader.exec_module(new_module)
  File "<frozen importlib._bootstrap_external>", line 843, in exec_module
  File "<frozen importlib._bootstrap>", line 219, in _call_with_frames_removed
  File "/opt/airflow/dags/star_wars_data_pipeline.py", line 14, in <module>
    from script_results import generate_results_json as generate_results_json
ModuleNotFoundError: No module named 'script_results'
[2024-02-13T19:03:26.185+0000] {processor.py:842} WARNING - No viable dags retrieved from /opt/airflow/dags/star_wars_data_pipeline.py
[2024-02-13T19:03:26.217+0000] {processor.py:183} INFO - Processing /opt/airflow/dags/star_wars_data_pipeline.py took 0.088 seconds
[2024-02-13T19:03:31.386+0000] {processor.py:161} INFO - Started process (PID=397) to work on /opt/airflow/dags/star_wars_data_pipeline.py
[2024-02-13T19:03:31.389+0000] {processor.py:830} INFO - Processing file /opt/airflow/dags/star_wars_data_pipeline.py for tasks to queue
[2024-02-13T19:03:31.394+0000] {logging_mixin.py:188} INFO - [2024-02-13T19:03:31.393+0000] {dagbag.py:538} INFO - Filling up the DagBag from /opt/airflow/dags/star_wars_data_pipeline.py
[2024-02-13T19:03:31.509+0000] {logging_mixin.py:188} INFO - [2024-02-13T19:03:31.501+0000] {dagbag.py:348} ERROR - Failed to import: /opt/airflow/dags/star_wars_data_pipeline.py
Traceback (most recent call last):
  File "/home/airflow/.local/lib/python3.8/site-packages/airflow/models/dagbag.py", line 344, in parse
    loader.exec_module(new_module)
  File "<frozen importlib._bootstrap_external>", line 843, in exec_module
  File "<frozen importlib._bootstrap>", line 219, in _call_with_frames_removed
  File "/opt/airflow/dags/star_wars_data_pipeline.py", line 14, in <module>
    from script_results import generate_results_json as generate_results_json
ModuleNotFoundError: No module named 'script_results'
[2024-02-13T19:03:31.514+0000] {processor.py:842} WARNING - No viable dags retrieved from /opt/airflow/dags/star_wars_data_pipeline.py
[2024-02-13T19:03:31.579+0000] {processor.py:183} INFO - Processing /opt/airflow/dags/star_wars_data_pipeline.py took 0.199 seconds
[2024-02-13T19:03:36.697+0000] {processor.py:161} INFO - Started process (PID=398) to work on /opt/airflow/dags/star_wars_data_pipeline.py
[2024-02-13T19:03:36.699+0000] {processor.py:830} INFO - Processing file /opt/airflow/dags/star_wars_data_pipeline.py for tasks to queue
[2024-02-13T19:03:36.708+0000] {logging_mixin.py:188} INFO - [2024-02-13T19:03:36.705+0000] {dagbag.py:538} INFO - Filling up the DagBag from /opt/airflow/dags/star_wars_data_pipeline.py
[2024-02-13T19:03:36.794+0000] {logging_mixin.py:188} INFO - [2024-02-13T19:03:36.784+0000] {dagbag.py:348} ERROR - Failed to import: /opt/airflow/dags/star_wars_data_pipeline.py
Traceback (most recent call last):
  File "/home/airflow/.local/lib/python3.8/site-packages/airflow/models/dagbag.py", line 344, in parse
    loader.exec_module(new_module)
  File "<frozen importlib._bootstrap_external>", line 843, in exec_module
  File "<frozen importlib._bootstrap>", line 219, in _call_with_frames_removed
  File "/opt/airflow/dags/star_wars_data_pipeline.py", line 14, in <module>
    from script_results import generate_results_json as generate_results_json
ModuleNotFoundError: No module named 'script_results'
[2024-02-13T19:03:36.800+0000] {processor.py:842} WARNING - No viable dags retrieved from /opt/airflow/dags/star_wars_data_pipeline.py
[2024-02-13T19:03:36.894+0000] {processor.py:183} INFO - Processing /opt/airflow/dags/star_wars_data_pipeline.py took 0.201 seconds
[2024-02-13T19:03:42.018+0000] {processor.py:161} INFO - Started process (PID=399) to work on /opt/airflow/dags/star_wars_data_pipeline.py
[2024-02-13T19:03:42.021+0000] {processor.py:830} INFO - Processing file /opt/airflow/dags/star_wars_data_pipeline.py for tasks to queue
[2024-02-13T19:03:42.025+0000] {logging_mixin.py:188} INFO - [2024-02-13T19:03:42.024+0000] {dagbag.py:538} INFO - Filling up the DagBag from /opt/airflow/dags/star_wars_data_pipeline.py
[2024-02-13T19:03:42.101+0000] {logging_mixin.py:188} INFO - [2024-02-13T19:03:42.094+0000] {dagbag.py:348} ERROR - Failed to import: /opt/airflow/dags/star_wars_data_pipeline.py
Traceback (most recent call last):
  File "/home/airflow/.local/lib/python3.8/site-packages/airflow/models/dagbag.py", line 344, in parse
    loader.exec_module(new_module)
  File "<frozen importlib._bootstrap_external>", line 843, in exec_module
  File "<frozen importlib._bootstrap>", line 219, in _call_with_frames_removed
  File "/opt/airflow/dags/star_wars_data_pipeline.py", line 14, in <module>
    from script_results import generate_results_json as generate_results_json
ModuleNotFoundError: No module named 'script_results'
[2024-02-13T19:03:42.104+0000] {processor.py:842} WARNING - No viable dags retrieved from /opt/airflow/dags/star_wars_data_pipeline.py
[2024-02-13T19:03:42.151+0000] {processor.py:183} INFO - Processing /opt/airflow/dags/star_wars_data_pipeline.py took 0.139 seconds
[2024-02-13T19:03:47.324+0000] {processor.py:161} INFO - Started process (PID=408) to work on /opt/airflow/dags/star_wars_data_pipeline.py
[2024-02-13T19:03:47.329+0000] {processor.py:830} INFO - Processing file /opt/airflow/dags/star_wars_data_pipeline.py for tasks to queue
[2024-02-13T19:03:47.335+0000] {logging_mixin.py:188} INFO - [2024-02-13T19:03:47.335+0000] {dagbag.py:538} INFO - Filling up the DagBag from /opt/airflow/dags/star_wars_data_pipeline.py
[2024-02-13T19:03:47.400+0000] {logging_mixin.py:188} INFO - [2024-02-13T19:03:47.392+0000] {dagbag.py:348} ERROR - Failed to import: /opt/airflow/dags/star_wars_data_pipeline.py
Traceback (most recent call last):
  File "/home/airflow/.local/lib/python3.8/site-packages/airflow/models/dagbag.py", line 344, in parse
    loader.exec_module(new_module)
  File "<frozen importlib._bootstrap_external>", line 843, in exec_module
  File "<frozen importlib._bootstrap>", line 219, in _call_with_frames_removed
  File "/opt/airflow/dags/star_wars_data_pipeline.py", line 14, in <module>
    from script_results import generate_results_json as generate_results_json
ModuleNotFoundError: No module named 'script_results'
[2024-02-13T19:03:47.402+0000] {processor.py:842} WARNING - No viable dags retrieved from /opt/airflow/dags/star_wars_data_pipeline.py
[2024-02-13T19:03:47.437+0000] {processor.py:183} INFO - Processing /opt/airflow/dags/star_wars_data_pipeline.py took 0.138 seconds
[2024-02-13T19:03:52.536+0000] {processor.py:161} INFO - Started process (PID=409) to work on /opt/airflow/dags/star_wars_data_pipeline.py
[2024-02-13T19:03:52.537+0000] {processor.py:830} INFO - Processing file /opt/airflow/dags/star_wars_data_pipeline.py for tasks to queue
[2024-02-13T19:03:52.540+0000] {logging_mixin.py:188} INFO - [2024-02-13T19:03:52.539+0000] {dagbag.py:538} INFO - Filling up the DagBag from /opt/airflow/dags/star_wars_data_pipeline.py
[2024-02-13T19:03:52.596+0000] {logging_mixin.py:188} INFO - [2024-02-13T19:03:52.591+0000] {dagbag.py:348} ERROR - Failed to import: /opt/airflow/dags/star_wars_data_pipeline.py
Traceback (most recent call last):
  File "/home/airflow/.local/lib/python3.8/site-packages/airflow/models/dagbag.py", line 344, in parse
    loader.exec_module(new_module)
  File "<frozen importlib._bootstrap_external>", line 843, in exec_module
  File "<frozen importlib._bootstrap>", line 219, in _call_with_frames_removed
  File "/opt/airflow/dags/star_wars_data_pipeline.py", line 14, in <module>
    from script_results import generate_results_json as generate_results_json
ModuleNotFoundError: No module named 'script_results'
[2024-02-13T19:03:52.599+0000] {processor.py:842} WARNING - No viable dags retrieved from /opt/airflow/dags/star_wars_data_pipeline.py
[2024-02-13T19:03:52.633+0000] {processor.py:183} INFO - Processing /opt/airflow/dags/star_wars_data_pipeline.py took 0.100 seconds
